Workbook
Name data: grafika!$O$4:$R$14
Name data: GW!$O$5:$R$14

Sheet GW
O2: August | P2: August | Q2: August | R2: September | S2: September | T2: September | U2: October | V2: October | W2: October | X2: November | Y2: November | Z2: November | AA2: November | AB2: December | AC2: December | AD2: December | AE2: December | AF2: December | AG2: December | AH2: January | AI2: January | AJ2: January | AK2: January | AL2: February | AM2: February | AN2: February | AO2: February | AP2: March | AQ2: March | AR2: April | AS2: April | AT2: April | AU2: April | AV2: April | AW2: May | AX2: May | AY2: May | AZ2: May
D3: Body | E3: cena přestupů | F3: Průměr | G3: Forma (5 kol) | H3: SD | I3: Max | J3: Min | L3: 1. half | M3: 2. half | O3: GW 01 | P3: GW 02 | Q3: GW 03 | R3: GW 04 | S3: GW 05 | T3: GW 06 | U3: GW 07 | V3: GW 08 | W3: GW 09 | X3: GW 10 | Y3: GW 11 | Z3: GW 12 | AA3: GW 13 | AB3: GW 14 | AC3: GW 15 | AD3: GW 16 | AE3: GW 17 | AF3: GW 18 | AG3: GW 19 | AH3: GW 20 | AI3: GW 21 | AJ3: GW 22 | AK3: GW 23 | AL3: GW 24 | AM3: GW 25 | AN3: GW 26 | AO3: GW 27 | AP3: GW 28 | AQ3: GW 29 | AR3: GW 30 | AS3: GW 31 | AT3: GW 32 | AU3: GW 33 | AV3: GW 34 | AW3: GW 35 | AX3: GW 36 | AY3: GW 37 | AZ3: GW 38 | BB3: Triple Captain | BC3: Bench boost | BD3: Ass man | BE3: Wildcard | BF3: Wildcard 2 | BG3: Freehit | BI3: Season 22/23 | BJ3: Season 22/23 | BK3: Season 22/23
B4: =_xlfn.RANK.EQ(D4,$D$4:$D$14) -> 1 | C4: Tomáš Kreps | D4: =SUM(O4:AZ4)-E4 -> 2457 | E4: 0 | F4: =AVERAGE(O4:AZ4) -> 64.657895 | G4: =SUM(OFFSET(O4,0,COUNTA(O4:AZ4)-5,1,5):AZ4) -> 307 | H4: =_xlfn.STDEV.P(O4:AZ4) -> 17.587789 | I4: =MAX(O4:AZ4) -> 118 | J4: =MIN(O4:AZ4) -> 29 | L4: =SUM(O4:AG4) -> 1200 | M4: =SUM(AH4:AZ4) -> 1257 | O4: 63 | P4: 73 | Q4: 82 | R4: 60 | S4: 73 | T4: 47 | U4: 50 | V4: 41 | W4: 74 | X4: 49 | Y4: 63 | Z4: 53 | AA4: 81 | AB4: 74 | AC4: 46 | AD4: 46 | AE4: 83 | AF4: 55 | AG4: 87 | AH4: 62 | AI4: 80 | AJ4: 48 | AK4: 50 | AL4: 118 | AM4: 89 | AN4: 82 | AO4: 65 | AP4: 65 | AQ4: 29 | AR4: 58 | AS4: 46 | AT4: 87 | AU4: 71 | AV4: 71 | AW4: 42 | AX4: 46 | AY4: 74 | AZ4: 74 | BB4: GW 32 | BC4: GW 33 | BD4: GW 24 | BE4: GW 16 | BF4: GW 31 | BG4: W 34 | BI4: - | BJ4: 2478 | BK4: 2499
B5: =_xlfn.RANK.EQ(D5,$D$4:$D$14) -> 2 | C5: Milan Pádivý | D5: =SUM(O5:AZ5)-E5 -> 2411 | E5: 4 | F5: =AVERAGE(O5:AZ5) -> 63.552632 | G5: =SUM(OFFSET(O5,0,COUNTA(O5:AZ5)-5,1,5):AZ5) -> 261 | H5: =_xlfn.STDEV.P(O5:AZ5) -> 17.330681 | I5: =MAX(O5:AZ5) -> 110 | J5: =MIN(O5:AZ5) -> 26 | L5: =SUM(O5:AG5) -> 1163 | M5: =SUM(AH5:AZ5) -> 1252 | O5: 94 | P5: 76 | Q5: 52 | R5: 26 | S5: 49 | T5: 106 | U5: 46 | V5: 59 | W5: 73 | X5: 54 | Y5: 79 | Z5: 58 | AA5: 65 | AB5: 52 | AC5: 67 | AD5: 46 | AE5: 50 | AF5: 63 | AG5: 48 | AH5: 76 | AI5: 72 | AJ5: 57 | AK5: 61 | AL5: 96 | AM5: 80 | AN5: 69 | AO5: 59 | AP5: 60 | AQ5: 61 | AR5: 70 | AS5: 53 | AT5: 110 | AU5: 67 | AV5: 53 | AW5: 50 | AX5: 35 | AY5: 60 | AZ5: 63 | BA5: 54 | BB5: GW 23 | BC5: GW 38 | BD5: GW 32 | BE5: GW 5 | BF5: GW 30 | BG5: GW 36 | BI5: 2101 | BJ5: 2166 | BK5: 2288
B6: =_xlfn.RANK.EQ(D6,$D$4:$D$14) -> 3 | C6: Josef Mokráň | D6: =SUM(O6:AZ6)-E6 -> 2344 | E6: 4 | F6: =AVERAGE(O6:AZ6) -> 61.789474 | G6: =SUM(OFFSET(O6,0,COUNTA(O6:AZ6)-5,1,5):AZ6) -> 288 | H6: =_xlfn.STDEV.P(O6:AZ6) -> 15.674582 | I6: =MAX(O6:AZ6) -> 95 | J6: =MIN(O6:AZ6) -> 31 | L6: =SUM(O6:AG6) -> 1079 | M6: =SUM(AH6:AZ6) -> 1269 | O6: 66 | P6: 84 | Q6: 65 | R6: 67 | S6: 62 | T6: 37 | U6: 49 | V6: 37 | W6: 48 | X6: 31 | Y6: 42 | Z6: 53 | AA6: 53 | AB6: 60 | AC6: 62 | AD6: 52 | AE6: 64 | AF6: 54 | AG6: 93 | AH6: 69 | AI6: 65 | AJ6: 43 | AK6: 59 | AL6: 95 | AM6: 77 | AN6: 85 | AO6: 76 | AP6: 66 | AQ6: 61 | AR6: 67 | AS6: 52 | AT6: 87 | AU6: 79 | AV6: 78 | AW6: 43 | AX6: 58 | AY6: 43 | AZ6: 66 | BB6: GW 9 | BC6: GW 36 | BD6: GW 30 | BE6: GW 12 | BF6: GW 34 | BG6: GW 29 | BI6: - | BJ6: 2466 | BK6: 2367
B7: =_xlfn.RANK.EQ(D7,$D$4:$D$14) -> 4 | C7: Milan Procházka | D7: =SUM(O7:AZ7)-E7 -> 2255 | E7: 0 | F7: =AVERAGE(O7:AZ7) -> 59.342105 | G7: =SUM(OFFSET(O7,0,COUNTA(O7:AZ7)-5,1,5):AZ7) -> 259 | H7: =_xlfn.STDEV.P(O7:AZ7) -> 16.627935 | I7: =MAX(O7:AZ7) -> 104 | J7: =MIN(O7:AZ7) -> 28 | L7: =SUM(O7:AG7) -> 1057 | M7: =SUM(AH7:AZ7) -> 1198 | O7: 56 | P7: 42 | Q7: 77 | R7: 60 | S7: 50 | T7: 60 | U7: 51 | V7: 28 | W7: 72 | X7: 33 | Y7: 51 | Z7: 37 | AA7: 56 | AB7: 58 | AC7: 80 | AD7: 54 | AE7: 56 | AF7: 58 | AG7: 78 | AH7: 84 | AI7: 59 | AJ7: 43 | AK7: 66 | AL7: 101 | AM7: 104 | AN7: 72 | AO7: 54 | AP7: 65 | AQ7: 56 | AR7: 52 | AS7: 37 | AT7: 64 | AU7: 82 | AV7: 54 | AW7: 49 | AX7: 48 | AY7: 44 | AZ7: 64 | BB7: GW 25 | BC7: GW 38 | BD7: GW 33 | BE7: GW 9 | BF7: GW 37 | BG7: GW 29 | BI7: 2131 | BJ7: 2471 | BK7: 2365
B8: =_xlfn.RANK.EQ(D8,$D$4:$D$14) -> 5 | C8: Martin Vácha | D8: =SUM(O8:AZ8)-E8 -> 2250 | E8: 8 | F8: =AVERAGE(O8:AZ8) -> 59.421053 | G8: =SUM(OFFSET(O8,0,COUNTA(O8:AZ8)-5,1,5):AZ8) -> 275 | H8: =_xlfn.STDEV.P(O8:AZ8) -> 18.650006 | I8: =MAX(O8:AZ8) -> 122 | J8: =MIN(O8:AZ8) -> 25 | L8: =SUM(O8:AG8) -> 1089 | M8: =SUM(AH8:AZ8) -> 1169 | O8: 53 | P8: 90 | Q8: 64 | R8: 37 | S8: 73 | T8: 81 | U8: 46 | V8: 50 | W8: 51 | X8: 56 | Y8: 36 | Z8: 52 | AA8: 55 | AB8: 59 | AC8: 73 | AD8: 25 | AE8: 66 | AF8: 53 | AG8: 69 | AH8: 57 | AI8: 93 | AJ8: 40 | AK8: 61 | AL8: 122 | AM8: 77 | AN8: 65 | AO8: 46 | AP8: 68 | AQ8: 31 | AR8: 46 | AS8: 46 | AT8: 76 | AU8: 66 | AV8: 75 | AW8: 44 | AX8: 66 | AY8: 52 | AZ8: 38 | BB8: GW 24 | BC8: GW 33 | BD8: GW 35 | BE8: GW 4 | BF8: GW 30 | BG8: GW 34 | BI8: - | BJ8: 2332 | BK8: 2352
B9: =_xlfn.RANK.EQ(D9,$D$4:$D$14) -> 6 | C9: Denis Dvořák | D9: =SUM(O9:AZ9)-E9 -> 2246 | E9: 0 | F9: =AVERAGE(O9:AZ9) -> 59.105263 | G9: =SUM(OFFSET(O9,0,COUNTA(O9:AZ9)-5,1,5):AZ9) -> 243 | H9: =_xlfn.STDEV.P(O9:AZ9) -> 18.723458 | I9: =MAX(O9:AZ9) -> 109 | J9: =MIN(O9:AZ9) -> 25 | L9: =SUM(O9:AG9) -> 1106 | M9: =SUM(AH9:AZ9) -> 1140 | O9: 37 | P9: 109 | Q9: 65 | R9: 60 | S9: 63 | T9: 55 | U9: 41 | V9: 25 | W9: 61 | X9: 40 | Y9: 47 | Z9: 42 | AA9: 83 | AB9: 86 | AC9: 46 | AD9: 65 | AE9: 50 | AF9: 46 | AG9: 85 | AH9: 50 | AI9: 59 | AJ9: 59 | AK9: 68 | AL9: 106 | AM9: 69 | AN9: 85 | AO9: 61 | AP9: 61 | AQ9: 54 | AR9: 45 | AS9: 34 | AT9: 85 | AU9: 61 | AV9: 61 | AW9: 40 | AX9: 55 | AY9: 46 | AZ9: 41 | BB9: GW 14 | BC9: GW 16 | BD9: GW 32 | BE9: GW 12 | BF9: GW 28 | BG9: GW 29 | BI9: - | BJ9: - | BK9: -
B10: =_xlfn.RANK.EQ(D10,$D$4:$D$14) -> 7 | C10: Miroslav Pádivý | D10: =SUM(O10:AZ10)-E10 -> 2214 | E10: 28 | F10: =AVERAGE(O10:AZ10) -> 59 | G10: =SUM(OFFSET(O10,0,COUNTA(O10:AZ10)-5,1,5):AZ10) -> 248 | H10: =_xlfn.STDEV.P(O10:AZ10) -> 18.782691 | I10: =MAX(O10:AZ10) -> 120 | J10: =MIN(O10:AZ10) -> 32 | L10: =SUM(O10:AG10) -> 1062 | M10: =SUM(AH10:AZ10) -> 1180 | O10: 60 | P10: 77 | Q10: 85 | R10: 33 | S10: 65 | T10: 58 | U10: 43 | V10: 38 | W10: 40 | X10: 41 | Y10: 52 | Z10: 49 | AA10: 63 | AB10: 77 | AC10: 58 | AD10: 47 | AE10: 61 | AF10: 62 | AG10: 53 | AH10: 46 | AI10: 72 | AJ10: 32 | AK10: 60 | AL10: 106 | AM10: 88 | AN10: 72 | AO10: 42 | AP10: 76 | AQ10: 65 | AR10: 62 | AS10: 46 | AT10: 120 | AU10: 45 | AV10: 54 | AW10: 38 | AX10: 49 | AY10: 52 | AZ10: 55 | BB10: GW 23 | BC10: GW 24 | BD10: GW 30 | BE10: GW 16 | BF10: GW 34 | BG10: GW 29 | BI10: 2267 | BJ10: 2372 | BK10: 2086
B11: =_xlfn.RANK.EQ(D11,$D$4:$D$14) -> 8 | C11: Martin Šípek | D11: =SUM(O11:AZ11)-E11 -> 2211 | E11: 12 | F11: =AVERAGE(O11:AZ11) -> 58.5 | G11: =SUM(OFFSET(O11,0,COUNTA(O11:AZ11)-5,1,5):AZ11) -> 287 | H11: =_xlfn.STDEV.P(O11:AZ11) -> 23.650693 | I11: =MAX(O11:AZ11) -> 140 | J11: =MIN(O11:AZ11) -> 14 | L11: =SUM(O11:AG11) -> 997 | M11: =SUM(AH11:AZ11) -> 1226 | O11: 75 | P11: 102 | Q11: 73 | R11: 53 | S11: 49 | T11: 53 | U11: 47 | V11: 14 | W11: 62 | X11: 29 | Y11: 45 | Z11: 25 | AA11: 91 | AB11: 30 | AC11: 57 | AD11: 59 | AE11: 25 | AF11: 46 | AG11: 62 | AH11: 57 | AI11: 51 | AJ11: 53 | AK11: 45 | AL11: 140 | AM11: 102 | AN11: 53 | AO11: 76 | AP11: 60 | AQ11: 90 | AR11: 56 | AS11: 32 | AT11: 68 | AU11: 56 | AV11: 69 | AW11: 44 | AX11: 56 | AY11: 59 | AZ11: 59 | BB11: GW 24 | BC11: GW 33 | BD11: GW 35 | BE11: GW 13 | BF11: GW 30 | BG11: GW 29 | BI11: 2179 | BJ11: 2378 | BK11: 2288
B12: =_xlfn.RANK.EQ(D12,$D$4:$D$14) -> 9 | C12: Tomáš Čedík | D12: =SUM(O12:AZ12)-E12 -> 2130 | E12: 0 | F12: =AVERAGE(O12:AZ12) -> 56.052632 | G12: =SUM(OFFSET(O12,0,COUNTA(O12:AZ12)-5,1,5):AZ12) -> 264 | H12: =_xlfn.STDEV.P(O12:AZ12) -> 22.388845 | I12: =MAX(O12:AZ12) -> 129 | J12: =MIN(O12:AZ12) -> 25 | L12: =SUM(O12:AG12) -> 916 | M12: =SUM(AH12:AZ12) -> 1214 | O12: 54 | P12: 53 | Q12: 29 | R12: 67 | S12: 77 | T12: 58 | U12: 76 | V12: 38 | W12: 36 | X12: 25 | Y12: 27 | Z12: 59 | AA12: 81 | AB12: 34 | AC12: 30 | AD12: 42 | AE12: 27 | AF12: 42 | AG12: 61 | AH12: 41 | AI12: 70 | AJ12: 26 | AK12: 81 | AL12: 129 | AM12: 77 | AN12: 86 | AO12: 62 | AP12: 94 | AQ12: 51 | AR12: 62 | AS12: 31 | AT12: 67 | AU12: 73 | AV12: 70 | AW12: 41 | AX12: 58 | AY12: 48 | AZ12: 47 | BB12: GW 24 | BD12: GW 28 | BF12: GW 23 | BI12: - | BJ12: 2275 | BK12: 2162
B13: =_xlfn.RANK.EQ(D13,$D$4:$D$14) -> 10 | C13: Miroslav Paňák | D13: =SUM(O13:AZ13)-E13 -> 1976 | E13: 0 | F13: =AVERAGE(O13:AZ13) -> 52 | G13: =SUM(OFFSET(O13,0,COUNTA(O13:AZ13)-5,1,5):AZ13) -> 230 | H13: =_xlfn.STDEV.P(O13:AZ13) -> 17.88413 | I13: =MAX(O13:AZ13) -> 102 | J13: =MIN(O13:AZ13) -> 25 | L13: =SUM(O13:AG13) -> 1064 | M13: =SUM(AH13:AZ13) -> 912 | O13: 49 | P13: 100 | Q13: 41 | R13: 39 | S13: 63 | T13: 102 | U13: 75 | V13: 34 | W13: 54 | X13: 26 | Y13: 39 | Z13: 75 | AA13: 79 | AB13: 57 | AC13: 65 | AD13: 53 | AE13: 27 | AF13: 48 | AG13: 38 | AH13: 61 | AI13: 57 | AJ13: 38 | AK13: 67 | AL13: 39 | AM13: 46 | AN13: 53 | AO13: 68 | AP13: 47 | AQ13: 30 | AR13: 40 | AS13: 25 | AT13: 47 | AU13: 64 | AV13: 51 | AW13: 34 | AX13: 44 | AY13: 49 | AZ13: 52 | BB13: GW 30 | BF13: GW 29 | BI13: 1798 | BJ13: 2136 | BK13: 2225
BI14: - | BJ14: 2263 | BK14: 2246
C16: FPL avg GW | D16: =SUM(O16:AZ16) -> 2008 | F16: =AVERAGE(O16:AZ16) -> 52.842105 | G16: =SUM(OFFSET(O16,0,COUNTA(O16:AZ16)-5,1,5)) -> 216 | H16: =STDEV(O16:AZ16) -> 10.791704 | I16: =MAX(O16:AZ16) -> 87 | J16: =MIN(O16:AZ16) -> 34 | L16: =SUM(O16:AD16) -> 837 | M16: =SUM(AE16:AZ16) -> 1171 | O16: 57 | P16: 69 | Q16: 64 | R16: 51 | S16: 58 | T16: 50 | U16: 46 | V16: 36 | W16: 54 | X16: 39 | Y16: 49 | Z16: 49 | AA16: 60 | AB16: 58 | AC16: 50 | AD16: 47 | AE16: 60 | AF16: 51 | AG16: 66 | AH16: 60 | AI16: 55 | AJ16: 46 | AK16: 59 | AL16: 87 | AM16: 74 | AN16: 62 | AO16: 53 | AP16: 52 | AQ16: 40 | AR16: 44 | AS16: 34 | AT16: 56 | AU16: 56 | AV16: 47 | AW16: 41 | AX16: 43 | AY16: 39 | AZ16: 46 | BI16: - | BJ16: 2020 | BK16: 2003
H18: Náš průměr kola | O18: =IF(SUM(O4:O14)>0,AVERAGE(O4:O14),"") -> 60.7 | P18: =IF(SUM(P4:P14)>0,AVERAGE(P4:P14),"") -> 80.6 | Q18: =IF(SUM(Q4:Q14)>0,AVERAGE(Q4:Q14),"") -> 63.3 | R18: =IF(SUM(R4:R14)>0,AVERAGE(R4:R14),"") -> 50.2 | S18: =IF(SUM(S4:S14)>0,AVERAGE(S4:S14),"") -> 62.4 | T18: =IF(SUM(T4:T14)>0,AVERAGE(T4:T14),"") -> 65.7 | U18: =IF(SUM(U4:U14)>0,AVERAGE(U4:U14),"") -> 52.4 | V18: =IF(SUM(V4:V14)>0,AVERAGE(V4:V14),"") -> 36.4 | ... AZ18: =IF(SUM(AZ4:AZ14)>0,AVERAGE(AZ4:AZ14),"") -> 55.9
H19: MAX of GW | O19: =IF(SUM(O4:O14)>0,MAX(O4:O14),"") -> 94 | P19: =IF(SUM(P4:P14)>0,MAX(P4:P14),"") -> 109 | Q19: =IF(SUM(Q4:Q14)>0,MAX(Q4:Q14),"") -> 85 | R19: =IF(SUM(R4:R14)>0,MAX(R4:R14),"") -> 67 | S19: =IF(SUM(S4:S14)>0,MAX(S4:S14),"") -> 77 | T19: =IF(SUM(T4:T14)>0,MAX(T4:T14),"") -> 106 | U19: =IF(SUM(U4:U14)>0,MAX(U4:U14),"") -> 76 | V19: =IF(SUM(V4:V14)>0,MAX(V4:V14),"") -> 59 | ... AZ19: =IF(SUM(AZ4:AZ14)>0,MAX(AZ4:AZ14),"") -> 74
H20: MIN of GW | O20: =IF(SUM(O4:O14)>0,MIN(O4:O14),"") -> 37 | P20: =IF(SUM(P4:P14)>0,MIN(P4:P14),"") -> 42 | Q20: =IF(SUM(Q4:Q14)>0,MIN(Q4:Q14),"") -> 29 | R20: =IF(SUM(R4:R14)>0,MIN(R4:R14),"") -> 26 | S20: =IF(SUM(S4:S14)>0,MIN(S4:S14),"") -> 49 | T20: =IF(SUM(T4:T14)>0,MIN(T4:T14),"") -> 37 | U20: =IF(SUM(U4:U14)>0,MIN(U4:U14),"") -> 41 | V20: =IF(SUM(V4:V14)>0,MIN(V4:V14),"") -> 14 | ... AZ20: =IF(SUM(AZ4:AZ14)>0,MIN(AZ4:AZ14),"") -> 38

Sheet grafika
Q1: neofiko
O2: August | P2: August | Q2: August | R2: September | S2: September | T2: September | U2: October | V2: October | W2: October | X2: November | Y2: November | Z2: November | AA2: November | AB2: December | AC2: December | AD2: December | AE2: December | AF2: December | AG2: December | AH2: January | AI2: January | AJ2: January | AK2: January | AL2: February | AM2: February | AN2: February | AO2: February | AP2: March | AQ2: March | AR2: April | AS2: April | AT2: April | AU2: April | AV2: April | AW2: May | AX2: May | AY2: May | AZ2: May
D3: Body | E3: cena přestupů | F3: Průměr | G3: Forma (5 kol) | H3: SD | I3: Max | J3: Min | L3: 1. half | M3: 2. half | O3: GW 01 | P3: GW 02 | Q3: GW 03 | R3: GW 04 | S3: GW 05 | T3: GW 06 | U3: GW 07 | V3: GW 08 | W3: GW 09 | X3: GW 10 | Y3: GW 11 | Z3: GW 12 | AA3: GW 13 | AB3: GW 14 | AC3: GW 15 | AD3: GW 16 | AE3: GW 17 | AF3: GW 18 | AG3: GW 19 | AH3: GW 20 | AI3: GW 21 | AJ3: GW 22 | AK3: GW 23 | AL3: GW 24 | AM3: GW 25 | AN3: GW 26 | AO3: GW 27 | AP3: GW 28 | AQ3: GW 29 | AR3: GW 30 | AS3: GW 31 | AT3: GW 32 | AU3: GW 33 | AV3: GW 34 | AW3: GW 35 | AX3: GW 36 | AY3: GW 37 | AZ3: GW 38 | BB3: Triple Captain | BC3: Bench boost | BD3: Mystery | BE3: Wildcard | BF3: Wildcard 2 | BG3: Freehit | BI3: Season 22/23 | BJ3: Season 22/23 | BK3: Season 22/23
B4: =_xlfn.RANK.EQ(D4,$D$4:$D$14) -> 3 | C4: Tomáš Kreps | D4: =SUM(O4:AZ4)-E4 -> 218 | E4: 0 | F4: =AVERAGE(O4:AZ4) -> 72.666667 | G4: =SUM(OFFSET(O4,0,COUNTA(O4:AZ4)-5,1,5):AZ4) -> 218 | H4: =_xlfn.STDEV.P(O4:AZ4) -> 7.7602978 | I4: =MAX(O4:AZ4) -> 82 | J4: =MIN(O4:AZ4) -> 63 | L4: =SUM(O4:AG4) -> 218 | M4: =SUM(AH4:AZ4) -> 0 | O4: 63 | P4: 73 | Q4: 82 | BI4: - | BJ4: 2478 | BK4: 2499
B5: =_xlfn.RANK.EQ(D5,$D$4:$D$14) -> 4 | C5: Josef Mokráň | D5: =SUM(O5:AZ5)-E5 -> 215 | E5: 0 | F5: =AVERAGE(O5:AZ5) -> 71.666667 | G5: =SUM(OFFSET(O5,0,COUNTA(O5:AZ5)-5,1,5):AZ5) -> 215 | H5: =_xlfn.STDEV.P(O5:AZ5) -> 8.7305339 | I5: =MAX(O5:AZ5) -> 84 | J5: =MIN(O5:AZ5) -> 65 | L5: =SUM(O5:AG5) -> 215 | M5: =SUM(AH5:AZ5) -> 0 | O5: 66 | P5: 84 | Q5: 65 | BI5: - | BJ5: 2466 | BK5: 2367
B6: =_xlfn.RANK.EQ(D6,$D$4:$D$14) -> 10 | C6: Milan Procházka | D6: =SUM(O6:AZ6)-E6 -> 175 | E6: 0 | F6: =AVERAGE(O6:AZ6) -> 58.333333 | G6: =SUM(OFFSET(O6,0,COUNTA(O6:AZ6)-5,1,5):AZ6) -> 175 | H6: =_xlfn.STDEV.P(O6:AZ6) -> 14.383633 | I6: =MAX(O6:AZ6) -> 77 | J6: =MIN(O6:AZ6) -> 42 | L6: =SUM(O6:AG6) -> 175 | M6: =SUM(AH6:AZ6) -> 0 | O6: 56 | P6: 42 | Q6: 77 | BI6: 2131 | BJ6: 2471 | BK6: 2365
B7: =_xlfn.RANK.EQ(D7,$D$4:$D$14) -> 7 | C7: Martin Vácha | D7: =SUM(O7:AZ7)-E7 -> 207 | E7: 0 | F7: =AVERAGE(O7:AZ7) -> 69 | G7: =SUM(OFFSET(O7,0,COUNTA(O7:AZ7)-5,1,5):AZ7) -> 207 | H7: =_xlfn.STDEV.P(O7:AZ7) -> 15.513435 | I7: =MAX(O7:AZ7) -> 90 | J7: =MIN(O7:AZ7) -> 53 | L7: =SUM(O7:AG7) -> 207 | M7: =SUM(AH7:AZ7) -> 0 | O7: 53 | P7: 90 | Q7: 64 | BI7: - | BJ7: 2332 | BK7: 2352
B8: =_xlfn.RANK.EQ(D8,$D$4:$D$14) -> 1 | C8: Martin Šípek | D8: =SUM(O8:AZ8)-E8 -> 250 | E8: 0 | F8: =AVERAGE(O8:AZ8) -> 83.333333 | G8: =SUM(OFFSET(O8,0,COUNTA(O8:AZ8)-5,1,5):AZ8) -> 250 | H8: =_xlfn.STDEV.P(O8:AZ8) -> 13.224556 | I8: =MAX(O8:AZ8) -> 102 | J8: =MIN(O8:AZ8) -> 73 | L8: =SUM(O8:AG8) -> 250 | M8: =SUM(AH8:AZ8) -> 0 | O8: 75 | P8: 102 | Q8: 73 | BI8: 2179 | BJ8: 2378 | BK8: 2288
B9: =_xlfn.RANK.EQ(D9,$D$4:$D$14) -> 2 | C9: Milan Pádivý | D9: =SUM(O9:AZ9)-E9 -> 222 | E9: 0 | F9: =AVERAGE(O9:AZ9) -> 74 | G9: =SUM(OFFSET(O9,0,COUNTA(O9:AZ9)-5,1,5):AZ9) -> 222 | H9: =_xlfn.STDEV.P(O9:AZ9) -> 17.204651 | I9: =MAX(O9:AZ9) -> 94 | J9: =MIN(O9:AZ9) -> 52 | L9: =SUM(O9:AG9) -> 222 | M9: =SUM(AH9:AZ9) -> 0 | O9: 94 | P9: 76 | Q9: 52 | BI9: 2101 | BJ9: 2166 | BK9: 2288
B10: =_xlfn.RANK.EQ(D10,$D$4:$D$14) -> 9 | C10: Michal Marek | D10: =SUM(O10:AZ10)-E10 -> 184 | E10: 0 | F10: =AVERAGE(O10:AZ10) -> 61.333333 | G10: =SUM(OFFSET(O10,0,COUNTA(O10:AZ10)-5,1,5):AZ10) -> 184 | H10: =_xlfn.STDEV.P(O10:AZ10) -> 10.077478 | I10: =MAX(O10:AZ10) -> 75 | J10: =MIN(O10:AZ10) -> 51 | L10: =SUM(O10:AG10) -> 184 | M10: =SUM(AH10:AZ10) -> 0 | O10: 51 | P10: 75 | Q10: 58 | BI10: - | BJ10: 2263 | BK10: 2246
B11: =_xlfn.RANK.EQ(D11,$D$4:$D$14) -> 8 | C11: Miroslav Paňák | D11: =SUM(O11:AZ11)-E11 -> 190 | E11: 0 | F11: =AVERAGE(O11:AZ11) -> 63.333333 | G11: =SUM(OFFSET(O11,0,COUNTA(O11:AZ11)-5,1,5):AZ11) -> 190 | H11: =_xlfn.STDEV.P(O11:AZ11) -> 26.132143 | I11: =MAX(O11:AZ11) -> 100 | J11: =MIN(O11:AZ11) -> 41 | L11: =SUM(O11:AG11) -> 190 | M11: =SUM(AH11:AZ11) -> 0 | O11: 49 | P11: 100 | Q11: 41 | BI11: 1798 | BJ11: 2136 | BK11: 2225
B12: =_xlfn.RANK.EQ(D12,$D$4:$D$14) -> 11 | C12: Tomáš Čedík | D12: =SUM(O12:AZ12)-E12 -> 136 | E12: 0 | F12: =AVERAGE(O12:AZ12) -> 45.333333 | G12: =SUM(OFFSET(O12,0,COUNTA(O12:AZ12)-5,1,5):AZ12) -> 136 | H12: =_xlfn.STDEV.P(O12:AZ12) -> 11.556624 | I12: =MAX(O12:AZ12) -> 54 | J12: =MIN(O12:AZ12) -> 29 | L12: =SUM(O12:AG12) -> 136 | M12: =SUM(AH12:AZ12) -> 0 | O12: 54 | P12: 53 | Q12: 29 | BI12: - | BJ12: 2275 | BK12: 2162
B13: =_xlfn.RANK.EQ(D13,$D$4:$D$14) -> 5 | C13: Miroslav Pádivý | D13: =SUM(O13:AZ13)-E13 -> 214 | E13: 4 | F13: =AVERAGE(O13:AZ13) -> 72.666667 | G13: =SUM(OFFSET(O13,0,COUNTA(O13:AZ13)-5,1,5):AZ13) -> 218 | H13: =_xlfn.STDEV.P(O13:AZ13) -> 9.1043335 | I13: =MAX(O13:AZ13) -> 81 | J13: =MIN(O13:AZ13) -> 60 | L13: =SUM(O13:AG13) -> 218 | M13: =SUM(AH13:AZ13) -> 0 | O13: 60 | P13: 77 | Q13: 81 | BI13: 2267 | BJ13: 2372 | BK13: 2086
B14: =_xlfn.RANK.EQ(D14,$D$4:$D$14) -> 6 | C14: Denis Dvořák | D14: =SUM(O14:AZ14)-E14 -> 209 | E14: 0 | F14: =AVERAGE(O14:AZ14) -> 69.666667 | G14: =SUM(OFFSET(O14,0,COUNTA(O14:AZ14)-5,1,5):AZ14) -> 209 | H14: =_xlfn.STDEV.P(O14:AZ14) -> 29.769485 | I14: =MAX(O14:AZ14) -> 109 | J14: =MIN(O14:AZ14) -> 37 | L14: =SUM(O14:AG14) -> 209 | M14: =SUM(AH14:AZ14) -> 0 | O14: 37 | P14: 109 | Q14: 63 | BI14: - | BJ14: - | BK14: -
C16: FPL avg GW | D16: =SUM(O16:AZ16) -> 126 | F16: =AVERAGE(O16:AZ16) -> 63 | G16: =SUM(OFFSET(O16,0,COUNTA(O16:AZ16)-5,1,5)) -> 252 | H16: =STDEV(O16:AZ16) -> 8.4852814 | I16: =MAX(O16:AZ16) -> 69 | J16: =MIN(O16:AZ16) -> 57 | L16: =SUM(O16:AD16) -> 126 | M16: =SUM(AE16:AZ16) -> 0 | O16: 57 | P16: 69 | BI16: - | BJ16: 2020 | BK16: 2003
H18: Náš průměr kola | O18: =IF(SUM(O4:O14)>0,AVERAGE(O4:O14),"") -> 59.818182 | P18: =IF(SUM(P4:P14)>0,AVERAGE(P4:P14),"") -> 80.090909 | Q18: =IF(SUM(Q4:Q14)>0,AVERAGE(Q4:Q14),"") -> 62.272727 | R18: =IF(SUM(R4:R14)>0,AVERAGE(R4:R14),"") | S18: =IF(SUM(S4:S14)>0,AVERAGE(S4:S14),"") | T18: =IF(SUM(T4:T14)>0,AVERAGE(T4:T14),"") | U18: =IF(SUM(U4:U14)>0,AVERAGE(U4:U14),"") | V18: =IF(SUM(V4:V14)>0,AVERAGE(V4:V14),"") | ... AZ18: =IF(SUM(AZ4:AZ14)>0,AVERAGE(AZ4:AZ14),"")
H19: MAX of GW | O19: =IF(SUM(O4:O14)>0,MAX(O4:O14),"") -> 94 | P19: =IF(SUM(P4:P14)>0,MAX(P4:P14),"") -> 109 | Q19: =IF(SUM(Q4:Q14)>0,MAX(Q4:Q14),"") -> 82 | R19: =IF(SUM(R4:R14)>0,MAX(R4:R14),"") | S19: =IF(SUM(S4:S14)>0,MAX(S4:S14),"") | T19: =IF(SUM(T4:T14)>0,MAX(T4:T14),"") | U19: =IF(SUM(U4:U14)>0,MAX(U4:U14),"") | V19: =IF(SUM(V4:V14)>0,MAX(V4:V14),"") | ... AZ19: =IF(SUM(AZ4:AZ14)>0,MAX(AZ4:AZ14),"")
H20: MIN of GW | O20: =IF(SUM(O4:O14)>0,MIN(O4:O14),"") -> 37 | P20: =IF(SUM(P4:P14)>0,MIN(P4:P14),"") -> 42 | Q20: =IF(SUM(Q4:Q14)>0,MIN(Q4:Q14),"") -> 29 | R20: =IF(SUM(R4:R14)>0,MIN(R4:R14),"") | S20: =IF(SUM(S4:S14)>0,MIN(S4:S14),"") | T20: =IF(SUM(T4:T14)>0,MIN(T4:T14),"") | U20: =IF(SUM(U4:U14)>0,MIN(U4:U14),"") | V20: =IF(SUM(V4:V14)>0,MIN(V4:V14),"") | ... AZ20: =IF(SUM(AZ4:AZ14)>0,MIN(AZ4:AZ14),"")

Sheet Stats
B2: TOP 25 Best Performance | I2: TOP 25 Worst Performance | Q2: Manager of the Month
B3: =_xlfn.RANK.EQ(C3,$C$3:$C$27) -> 1 | C3: 109 | D3: Denis Dvořák | E3: GW 02 | F3: =LARGE(GW!$O$4:$AZ$14,Stats!B3)-C3 -> 31 | I3: =_xlfn.RANK.EQ(J3,$J$3:$J$27,1) -> 1 | J3: 14 | K3: Martin Šípek | L3: GW 08 | M3: =SMALL(GW!$O$5:$AZ$14,Stats!I3)-J3 -> 0 | P3: # GW | R3: 1 | U3: 2 | X3: 3
B4: =_xlfn.RANK.EQ(C4,$C$3:$C$27) -> 2 | C4: 106 | D4: Milan Pádivý | E4: GW 06 | F4: =LARGE(GW!$O$4:$AZ$14,Stats!B4)-C4 -> 23 | I4: =_xlfn.RANK.EQ(J4,$J$3:$J$27,1) -> 2 | J4: 25 | K4: Denis Dvořák | L4: GW 08 | M4: =SMALL(GW!$O$5:$AZ$14,Stats!I4)-J4 -> 0 | P4: =COUNTIF(GW!$2:$2,Stats!Q4) -> 3 | Q4: August | R4: =VLOOKUP(R$3,'Pomocný'!$C$16:$M$26,11,FALSE) -> Martin Šípek | S4: =VLOOKUP(R4,'Pomocný'!$B:$L,2,FALSE) -> 250 | U4: Milan Pádivý | V4: =VLOOKUP(U4,'Pomocný'!$B:$L,2,FALSE) -> 222 | X4: Miroslav Pádivý | Y4: =VLOOKUP(X4,'Pomocný'!$B:$L,2,FALSE) -> 222
B5: =_xlfn.RANK.EQ(C5,$C$3:$C$27) -> 3 | C5: 102 | D5: Martin Šípek | E5: GW 02 | F5: =LARGE(GW!$O$4:$AZ$14,Stats!B5)-C5 -> 20 | I5: =_xlfn.RANK.EQ(J5,$J$3:$J$27,1) -> 2 | J5: 25 | K5: Tomáš Čedík | L5: GW 10 | M5: =SMALL(GW!$O$5:$AZ$14,Stats!I5)-J5 -> 0 | P5: =COUNTIF(GW!$2:$2,Stats!Q5) -> 3 | Q5: September | R5: =VLOOKUP(R$3,'Pomocný'!$D16:$M$26,10,FALSE) -> Miroslav Paňák | S5: =VLOOKUP(R5,'Pomocný'!$B:$L,3,FALSE) -> 204 | U5: =VLOOKUP(U$3,'Pomocný'!$D16:$M$26,10,FALSE) -> Tomáš Čedík | V5: =VLOOKUP(U5,'Pomocný'!$B:$L,3,FALSE) -> 202 | X5: =VLOOKUP(X$3,'Pomocný'!$D16:$M$26,10,FALSE) -> Martin Vácha | Y5: =VLOOKUP(X5,'Pomocný'!$B:$L,3,FALSE) -> 191
B6: =_xlfn.RANK.EQ(C6,$C$3:$C$27) -> 3 | C6: 102 | D6: Miroslav Paňák | E6: GW 06 | F6: =LARGE(GW!$O$4:$AZ$14,Stats!B6)-C6 -> 20 | I6: =_xlfn.RANK.EQ(J6,$J$3:$J$27,1) -> 2 | J6: 25 | K6: Martin Šípek | L6: GW 12 | M6: =SMALL(GW!$O$5:$AZ$14,Stats!I6)-J6 -> 0 | P6: =COUNTIF(GW!$2:$2,Stats!Q6) -> 3 | Q6: October | R6: =VLOOKUP(R$3,'Pomocný'!$E16:$M$26,9,FALSE) -> Milan Pádivý | S6: =VLOOKUP(R6,'Pomocný'!$B:$L,4,FALSE) -> 178 | U6: =VLOOKUP(U$3,'Pomocný'!$E16:$M$26,9,FALSE) -> Tomáš Kreps | V6: =VLOOKUP(U6,'Pomocný'!$B:$L,4,FALSE) -> 165 | X6: =VLOOKUP(X$3,'Pomocný'!$E16:$M$26,9,FALSE) -> Miroslav Paňák | Y6: =VLOOKUP(X6,'Pomocný'!$B:$L,4,FALSE) -> 163
B7: =_xlfn.RANK.EQ(C7,$C$3:$C$27) -> 5 | C7: 100 | D7: Miroslav Paňák | E7: GW 02 | F7: =LARGE(GW!$O$4:$AZ$14,Stats!B7)-C7 -> 18 | I7: =_xlfn.RANK.EQ(J7,$J$3:$J$27,1) -> 5 | J7: 26 | K7: Milan Pádivý | L7: GW 04 | M7: =SMALL(GW!$O$5:$AZ$14,Stats!I7)-J7 -> -1 | P7: =COUNTIF(GW!$2:$2,Stats!Q7) -> 4 | Q7: November | R7: =VLOOKUP(R$3,'Pomocný'!F$16:$M$26,8,FALSE) -> Milan Pádivý | S7: =VLOOKUP(R7,'Pomocný'!$B:$L,5,FALSE) -> 256 | U7: Tomáš Kreps | V7: =VLOOKUP(U7,'Pomocný'!$B:$L,5,FALSE) -> 246 | X7: Miroslav Pádivý | Y7: =VLOOKUP(X7,'Pomocný'!$B:$L,5,FALSE) -> 205
B8: =_xlfn.RANK.EQ(C8,$C$3:$C$27) -> 6 | C8: 94 | D8: Milan Pádivý | E8: GW 01 | F8: =LARGE(GW!$O$4:$AZ$14,Stats!B8)-C8 -> 16 | I8: =_xlfn.RANK.EQ(J8,$J$3:$J$27,1) -> 5 | J8: 26 | K8: Miroslav Paňák | L8: GW 10 | M8: =SMALL(GW!$O$5:$AZ$14,Stats!I8)-J8 -> -1 | P8: =COUNTIF(GW!$2:$2,Stats!Q8) -> 6 | Q8: December | R8: =VLOOKUP(R$3,'Pomocný'!G$16:$M$26,7,FALSE) -> Tomáš Kreps | S8: =VLOOKUP(R8,'Pomocný'!$B:$L,6,FALSE) -> 391 | U8: Milan Pádivý | V8: =VLOOKUP(U8,'Pomocný'!$B:$L,6,FALSE) -> 326 | X8: Martin Vácha | Y8: =VLOOKUP(X8,'Pomocný'!$B:$L,6,FALSE) -> 345
B9: =_xlfn.RANK.EQ(C9,$C$3:$C$27) -> 7 | C9: 91 | D9: Martin Šípek | E9: GW 13 | F9: =LARGE(GW!$O$4:$AZ$14,Stats!B9)-C9 -> 18 | I9: =_xlfn.RANK.EQ(J9,$J$3:$J$27,1) -> 7 | J9: 27 | K9: Tomáš Čedík | L9: GW 11 | M9: =SMALL(GW!$O$5:$AZ$14,Stats!I9)-J9 -> -2 | P9: =COUNTIF(GW!$2:$2,Stats!Q9) -> 4 | Q9: January | R9: =VLOOKUP(R$3,'Pomocný'!H$16:$M$26,6,FALSE) -> Milan Pádivý | S9: =VLOOKUP(R9,'Pomocný'!$B:$L,7,FALSE) -> 266 | U9: =VLOOKUP(U$3,'Pomocný'!H$16:$M$26,6,FALSE) -> Milan Procházka | V9: =VLOOKUP(U9,'Pomocný'!$B:$L,7,FALSE) -> 252 | X9: =VLOOKUP(X$3,'Pomocný'!H$16:$M$26,6,FALSE) -> Martin Vácha | Y9: =VLOOKUP(X9,'Pomocný'!$B:$L,7,FALSE) -> 251
B10: =_xlfn.RANK.EQ(C10,$C$3:$C$27) -> 8 | C10: 90 | D10: Martin Vácha | E10: GW 02 | F10: =LARGE(GW!$O$4:$AZ$14,Stats!B10)-C10 -> 16 | I10: =_xlfn.RANK.EQ(J10,$J$3:$J$27,1) -> 8 | J10: 28 | K10: Milan Procházka | L10: GW 08 | M10: =SMALL(GW!$O$5:$AZ$14,Stats!I10)-J10 -> -2 | P10: =COUNTIF(GW!$2:$2,Stats!Q10) -> 4 | Q10: February | R10: =VLOOKUP(R$3,'Pomocný'!I$16:$M$26,5,FALSE) -> Martin Šípek | S10: =VLOOKUP(R10,'Pomocný'!$B:$L,8,FALSE) -> 371 | U10: =VLOOKUP(U$3,'Pomocný'!$D21:$M$26,10,FALSE) -> Tomáš Čedík | V10: =VLOOKUP(U10,'Pomocný'!$B:$L,8,FALSE) -> 354 | X10: Tomáš Kreps | Y10: =VLOOKUP(X10,'Pomocný'!$B:$L,8,FALSE) -> 354
B11: =_xlfn.RANK.EQ(C11,$C$3:$C$27) -> 9 | C11: 86 | D11: Denis Dvořák | E11: GW 14 | F11: =LARGE(GW!$O$4:$AZ$14,Stats!B11)-C11 -> 20 | I11: =_xlfn.RANK.EQ(J11,$J$3:$J$27,1) -> 9 | J11: 29 | K11: Tomáš Čedík | L11: GW 03 | M11: =SMALL(GW!$O$5:$AZ$14,Stats!I11)-J11 -> -3 | P11: =COUNTIF(GW!$2:$2,Stats!Q11) -> 2 | Q11: March | R11: =VLOOKUP(R$3,'Pomocný'!J$16:$M$26,4,FALSE) -> Martin Šípek | S11: =VLOOKUP(R11,'Pomocný'!$B:$L,9,FALSE) -> 150 | U11: =VLOOKUP(U$3,'Pomocný'!J$16:$M$26,4,FALSE) -> Tomáš Čedík | V11: =VLOOKUP(U11,'Pomocný'!$B:$L,9,FALSE) -> 145 | X11: =VLOOKUP(X$3,'Pomocný'!J$16:$M$26,4,FALSE) -> Miroslav Pádivý | Y11: =VLOOKUP(X11,'Pomocný'!$B:$L,9,FALSE) -> 141
B12: =_xlfn.RANK.EQ(C12,$C$3:$C$27) -> 10 | C12: 85 | D12: Miroslav Pádivý | E12: GW 03 | F12: =LARGE(GW!$O$4:$AZ$14,Stats!B12)-C12 -> 21 | I12: =_xlfn.RANK.EQ(J12,$J$3:$J$27,1) -> 9 | J12: 29 | K12: Martin Šípek | L12: GW 10 | M12: =SMALL(GW!$O$5:$AZ$14,Stats!I12)-J12 -> -3 | P12: =COUNTIF(GW!$2:$2,Stats!Q12) -> 5 | Q12: April | R12: =VLOOKUP(R$3,'Pomocný'!K$16:$M$26,3,FALSE) -> Josef Mokráň | S12: =VLOOKUP(R12,'Pomocný'!$B:$L,10,FALSE) -> 363 | U12: =VLOOKUP(U$3,'Pomocný'!K$16:$M$26,3,FALSE) -> Milan Pádivý | V12: =VLOOKUP(U12,'Pomocný'!$B:$L,10,FALSE) -> 353 | X12: =VLOOKUP(X$3,'Pomocný'!K$16:$M$26,3,FALSE) -> Tomáš Kreps | Y12: =VLOOKUP(X12,'Pomocný'!$B:$L,10,FALSE) -> 333
B13: =_xlfn.RANK.EQ(C13,$C$3:$C$27) -> 11 | C13: 84 | D13: Josef Mokráň | E13: GW 02 | F13: =LARGE(GW!$O$4:$AZ$14,Stats!B13)-C13 -> 20 | I13: =_xlfn.RANK.EQ(J13,$J$3:$J$27,1) -> 11 | J13: 30 | K13: Martin Šípek | L13: GW 14 | M13: =SMALL(GW!$O$5:$AZ$14,Stats!I13)-J13 -> -3 | P13: =COUNTIF(GW!$2:$2,Stats!Q13) -> 4 | Q13: May | R13: =VLOOKUP(R$3,'Pomocný'!L$16:$M$26,2,FALSE) -> Tomáš Kreps | S13: =VLOOKUP(R13,'Pomocný'!$B:$L,11,FALSE) -> 236 | U13: =VLOOKUP(U$3,'Pomocný'!L$16:$M$26,2,FALSE) -> Martin Šípek | V13: =VLOOKUP(U13,'Pomocný'!$B:$L,11,FALSE) -> 218 | X13: =VLOOKUP(X$3,'Pomocný'!L$16:$M$26,2,FALSE) -> Josef Mokráň | Y13: =VLOOKUP(X13,'Pomocný'!$B:$L,11,FALSE) -> 210
B14: =_xlfn.RANK.EQ(C14,$C$3:$C$27) -> 12 | C14: 83 | D14: Denis Dvořák | E14: GW 13 | F14: =LARGE(GW!$O$4:$AZ$14,Stats!B14)-C14 -> 19 | I14: =_xlfn.RANK.EQ(J14,$J$3:$J$27,1) -> 11 | J14: 30 | K14: Tomáš Čedík | L14: GW 15 | M14: =SMALL(GW!$O$5:$AZ$14,Stats!I14)-J14 -> -3
B15: =_xlfn.RANK.EQ(C15,$C$3:$C$27) -> 13 | C15: 82 | D15: Tomáš Kreps | E15: GW 03 | F15: =LARGE(GW!$O$4:$AZ$14,Stats!B15)-C15 -> 20 | I15: =_xlfn.RANK.EQ(J15,$J$3:$J$27,1) -> 13 | J15: 31 | K15: Josef Mokráň | L15: GW 10 | M15: =SMALL(GW!$O$5:$AZ$14,Stats!I15)-J15 -> -4
B16: =_xlfn.RANK.EQ(C16,$C$3:$C$27) -> 14 | C16: 81 | D16: Martin Vácha | E16: GW 06 | F16: =LARGE(GW!$O$4:$AZ$14,Stats!B16)-C16 -> 21 | I16: =_xlfn.RANK.EQ(J16,$J$3:$J$27,1) -> 14 | J16: 33 | K16: Miroslav Pádivý | L16: GW 04 | M16: =SMALL(GW!$O$5:$AZ$14,Stats!I16)-J16 -> -5 | R16: Winner of the GW | V16: Loser of the GW
B17: =_xlfn.RANK.EQ(C17,$C$3:$C$27) -> 14 | C17: 81 | D17: Tomáš Kreps | E17: GW 13 | F17: =LARGE(GW!$O$4:$AZ$14,Stats!B17)-C17 -> 21 | I17: =_xlfn.RANK.EQ(J17,$J$3:$J$27,1) -> 14 | J17: 33 | K17: Milan Procházka | L17: GW 10 | M17: =SMALL(GW!$O$5:$AZ$14,Stats!I17)-J17 -> -5 | Q17: =_xlfn.RANK.EQ(S17,$S$17:$S$27,0) -> 2 | R17: Tomáš Čedík | S17: =VLOOKUP(R17,'Pomocný'!$O:$P,2,FALSE) -> 6 | V17: =_xlfn.RANK.EQ(Y17,$Y$17:$Y$26,0) -> 2 | X17: Tomáš Čedík | Y17: =VLOOKUP(X17,'Pomocný'!$O$16:$P$26,2,FALSE) -> 8
B18: =_xlfn.RANK.EQ(C18,$C$3:$C$27) -> 14 | C18: 81 | D18: Tomáš Čedík | E18: GW 13 | F18: =LARGE(GW!$O$4:$AZ$14,Stats!B18)-C18 -> 21 | I18: =_xlfn.RANK.EQ(J18,$J$3:$J$27,1) -> 16 | J18: 34 | K18: Miroslav Paňák | L18: GW 08 | M18: =SMALL(GW!$O$5:$AZ$14,Stats!I18)-J18 -> -5 | Q18: =_xlfn.RANK.EQ(S18,$S$17:$S$27,0) -> 1 | R18: Milan Pádivý | S18: =VLOOKUP(R18,'Pomocný'!$O:$P,2,FALSE) -> 8 | V18: =_xlfn.RANK.EQ(Y18,$Y$17:$Y$26,0) -> 2 | X18: Martin Šípek | Y18: =VLOOKUP(X18,'Pomocný'!$O$16:$P$26,2,FALSE) -> 8
F19: =LARGE(GW!$O$5:$AZ$14,Stats!B19)-C19 -> #NUM! | I19: =_xlfn.RANK.EQ(J19,$J$3:$J$27,1) -> 16 | J19: 34 | K19: Tomáš Čedík | L19: GW 14 | M19: =SMALL(GW!$O$5:$AZ$14,Stats!I19)-J19 -> -5 | Q19: =_xlfn.RANK.EQ(S19,$S$17:$S$27,0) -> 3 | R19: Denis Dvořák | S19: =VLOOKUP(R19,'Pomocný'!$O:$P,2,FALSE) -> 4 | V19: =_xlfn.RANK.EQ(Y19,$Y$17:$Y$26,0) -> 1 | X19: Miroslav Paňák | Y19: =VLOOKUP(X19,'Pomocný'!$O$16:$P$26,2,FALSE) -> 10
F20: =LARGE(GW!$O$5:$AZ$14,Stats!B20)-C20 -> #NUM! | M20: =SMALL(GW!$O$5:$AZ$14,Stats!I20)-J20 -> #NUM! | Q20: =_xlfn.RANK.EQ(S20,$S$17:$S$27,0) -> 3 | R20: Martin Šípek | S20: =VLOOKUP(R20,'Pomocný'!$O:$P,2,FALSE) -> 4 | V20: =_xlfn.RANK.EQ(Y20,$Y$17:$Y$26,0) -> 6 | X20: Denis Dvořák | Y20: =VLOOKUP(X20,'Pomocný'!$O$16:$P$26,2,FALSE) -> 2
F21: =LARGE(GW!$O$5:$AZ$14,Stats!B21)-C21 -> #NUM! | M21: =SMALL(GW!$O$5:$AZ$14,Stats!I21)-J21 -> #NUM! | Q21: =_xlfn.RANK.EQ(S21,$S$17:$S$27,0) -> 3 | R21: Josef Mokráň | S21: =VLOOKUP(R21,'Pomocný'!$O:$P,2,FALSE) -> 4 | V21: =_xlfn.RANK.EQ(Y21,$Y$17:$Y$26,0) -> 4 | X21: Josef Mokráň | Y21: =VLOOKUP(X21,'Pomocný'!$O$16:$P$26,2,FALSE) -> 3
F22: =LARGE(GW!$O$5:$AZ$14,Stats!B22)-C22 -> #NUM! | M22: =SMALL(GW!$O$5:$AZ$14,Stats!I22)-J22 -> #NUM! | Q22: =_xlfn.RANK.EQ(S22,$S$17:$S$27,0) -> 3 | R22: Milan Procházka | S22: =VLOOKUP(R22,'Pomocný'!$O:$P,2,FALSE) -> 4 | V22: =_xlfn.RANK.EQ(Y22,$Y$17:$Y$26,0) -> 4 | X22: Milan Pádivý | Y22: =VLOOKUP(X22,'Pomocný'!$O$16:$P$26,2,FALSE) -> 3
F23: =LARGE(GW!$O$5:$AZ$14,Stats!B23)-C23 -> #NUM! | M23: =SMALL(GW!$O$5:$AZ$14,Stats!I23)-J23 -> #NUM! | Q23: =_xlfn.RANK.EQ(S23,$S$17:$S$27,0) -> 10 | R23: Miroslav Paňák | S23: =VLOOKUP(R23,'Pomocný'!$O:$P,2,FALSE) -> 1 | V23: =_xlfn.RANK.EQ(Y23,$Y$17:$Y$26,0) -> 9 | X23: Milan Procházka | Y23: =VLOOKUP(X23,'Pomocný'!$O$16:$P$26,2,FALSE) -> 1
F24: =LARGE(GW!$O$5:$AZ$14,Stats!B24)-C24 -> #NUM! | M24: =SMALL(GW!$O$5:$AZ$14,Stats!I24)-J24 -> #NUM! | Q24: =_xlfn.RANK.EQ(S24,$S$17:$S$27,0) -> 3 | R24: Tomáš Kreps | S24: =VLOOKUP(R24,'Pomocný'!$O:$P,2,FALSE) -> 4 | V24: =_xlfn.RANK.EQ(Y24,$Y$17:$Y$26,0) -> 6 | X24: Miroslav Pádivý | Y24: =VLOOKUP(X24,'Pomocný'!$O$16:$P$26,2,FALSE) -> 2
F25: =LARGE(GW!$O$5:$AZ$14,Stats!B25)-C25 -> #NUM! | M25: =SMALL(GW!$O$5:$AZ$14,Stats!I25)-J25 -> #NUM! | Q25: =_xlfn.RANK.EQ(S25,$S$17:$S$27,0) -> 8 | R25: Martin Vácha | S25: =VLOOKUP(R25,'Pomocný'!$O:$P,2,FALSE) -> 3 | V25: =_xlfn.RANK.EQ(Y25,$Y$17:$Y$26,0) -> 6 | X25: Martin Vácha | Y25: =VLOOKUP(X25,'Pomocný'!$O$16:$P$26,2,FALSE) -> 2
F26: =LARGE(GW!$O$5:$AZ$14,Stats!B26)-C26 -> #NUM! | M26: =SMALL(GW!$O$5:$AZ$14,Stats!I26)-J26 -> #NUM! | Q26: =_xlfn.RANK.EQ(S26,$S$17:$S$27,0) -> 9 | R26: Miroslav Pádivý | S26: =VLOOKUP(R26,'Pomocný'!$O:$P,2,FALSE) -> 2 | V26: =_xlfn.RANK.EQ(Y26,$Y$17:$Y$26,0) -> 9 | X26: Tomáš Kreps | Y26: =VLOOKUP(X26,'Pomocný'!$O$16:$P$26,2,FALSE) -> 1
F27: =LARGE(GW!$O$5:$AZ$14,Stats!B27)-C27 -> #NUM! | M27: =SMALL(GW!$O$5:$AZ$14,Stats!I27)-J27 -> #NUM!

Sheet Chips+Captain
C2: Triple Captain use | J2: Assistan manager
D3: GW | E3: Captain | F3: C. points | G3: extra | H3: opp | K3: GW | L3: Manager | M3: opp | N3: points
B4: 1 | C4: Tomáš Kreps | D4: GW 32 | E4: Isak | F4: 33 | G4: =F4/3 -> 11 | H4: MUN; CRY | J4: Tomáš Kreps | K4: 24-26 | L4: Slot, Slot, Arteta | M4: bou+eve; WOL+avl; WHU | N4: 28
B5: 2 | C5: Milan Pádivý | D5: GW 23 | E5: Salah | F5: 24 | G5: =F5/3 -> 8 | H5: IPS | J5: Milan Pádivý | K5: 32-34 | L5: Howe, Arteta, Howe | M5: MUN+CRY; ips+CRY; IPS | N5: 51
B6: 3 | C6: Josef Mokráň | D6: GW 9 | E6: Haaland | F6: 18 | G6: =F6/3 -> 6 | H6: SOU | J6: Josef Mokráň | K6: 30-32 | L6: Howe, Howe, Howe | M6: BRE; lei; MUN+CRY | N6: 42
B7: 4 | C7: Milan Procházka | D7: GW 25 | E7: Salah | F7: 60 | G7: =F7/3 -> 20 | H7: WOL; avl | J7: Milan Procházka | K7: 33-35 | L7: Glasner, Amorin, Amorin | M7: BOU+ars; bou; bre | N7: 27
B8: 5 | C8: Martin Vácha | D8: GW 24 | E8: Salah | F8: 87 | G8: =F8/3 -> 29 | H8: bou; eve | J8: Martin Vácha | K8: 35-37 | L8: Glasner, Glasner, Glasner | M8: NFO; tot; WOL | N8: 29
B9: 6 | C9: Denis Dvořák | D9: GW 14 | E9: Salah | F9: 54 | G9: =F9/3 -> 18 | H9: new | J9: Denis Dvořák | K9: 32-34 | L9: Howe, Arteta, Howe | M9: MUN+CRY; ips+CRY; IPS | N9: 51
B10: 7 | C10: Miroslav Pádivý | D10: GW 23 | E10: Salah | F10: 24 | G10: =F10/3 -> 8 | H10: IPS | J10: Miroslav Pádivý | K10: 30-32 | L10: Howe, Howe, Howe | M10: BRE; lei; MUN+CRY | N10: 42
B11: 8 | C11: Martin Šípek | D11: GW 24 | E11: Salah | F11: 87 | G11: =F11/3 -> 29 | H11: bou; eve | J11: Martin Šípek | K11: 35-37 | L11: Nuno, Nuno, Nuno | M11: cry; LEI; whu | N11: 17
B12: 9 | C12: Tomáš Čedík | D12: GW 24 | E12: Salah | F12: 87 | G12: =F12/3 -> 29 | H12: bou; eve | J12: Tomáš Čedík | K12: 28-30 | L12: Slot, Nuno, Nuno | M12: SOU; ips; MUN | N12: =28 -> 28
B13: 10 | C13: Miroslav Paňák | D13: GW 30 | E13: Salah | F13: 9 | G13: =F13/3 -> 3 | H13: EVE | J13: Miroslav Paňák
D15: Captain points | K15: Bench points (bez BB)
B16: 1 | C16: Tomáš Kreps | D16: 343 | J16: Tomáš Kreps
B17: 2 | C17: Milan Pádivý | D17: 326 | J17: Milan Pádivý
B18: 3 | C18: Josef Mokráň | D18: 300 | J18: Josef Mokráň
B19: 4 | C19: Milan Procházka | D19: 264 | J19: Milan Procházka
B20: 5 | C20: Martin Vácha | D20: 285 | J20: Martin Vácha
B21: 6 | C21: Denis Dvořák | D21: 310 | J21: Denis Dvořák
B22: 7 | C22: Miroslav Pádivý | D22: 346 | J22: Miroslav Pádivý
B23: 8 | C23: Martin Šípek | D23: 267 | J23: Martin Šípek
B24: 9 | C24: Tomáš Čedík | D24: 219 | J24: Tomáš Čedík
B25: 10 | C25: Miroslav Paňák | D25: 223 | J25: Miroslav Paňák
C26: Salah | D26: 344

Sheet Season review
B1: https://www.fpl-data.co.uk/season_review
B2: Player name | C2: Tomáš Kreps | D2: Josef Mokráň | E2: Milan Procházka | F2: Martin Vácha | G2: Martin Šípek | H2: Milan Pádivý | I2: Michal Marek | J2: Miroslav Paňák | K2: Tomáš Čedík | L2: Miroslav Pádivý | M2: Jakub Doležal | N2: Jan Rosol | O2: Martin Čech
B3: Total Points | C3: 2499 | D3: 2367 | E3: 2365 | F3: 2352 | G3: 2288 | H3: 2288 | I3: 2246 | J3: 2225 | K3: 2162 | L3: 2086 | M3: 2078 | N3: 2073 | O3: 1780
B4: Overall rank | C4: 77390 | D4: 532173 | E4: 542886 | F4: 627889 | G4: 1152295 | H4: 1150497 | I4: 1608819 | J4: 1859387 | K4: 2691231 | L4: 3718044 | M4: 3813381 | N4: 3882995 | O4: 7439805
B5: Squad Value | C5: 1055 | D5: 1037 | E5: 1031 | F5: 1021 | G5: 1039 | H5: 1021 | I5: 1015 | J5: 996 | K5: 1012 | L5: 1010 | M5: 1000 | N5: 999 | O5: 1006
B6: Highest week rank | C6: 191612 | D6: 268324 | E6: 214514 | F6: 57759 | G6: 56176 | H6: 323260 | I6: 248116 | J6: 408733 | K6: 19016 | L6: 237122 | M6: 108702 | N6: 194198 | O6: 418170
B7: Highest overall rank | C7: 67707 | D7: 258316 | E7: 214514 | F7: 534119 | G7: 721548 | H7: 620461 | I7: 1086049 | J7: 1201771 | K7: 887541 | L7: 1865346 | M7: 1089975 | N7: 3696223 | O7: 4287117
B9: Total transfers | C9: 38 | D9: 38 | E9: 34 | F9: 44 | G9: 39 | H9: 35 | I9: 41 | J9: 29 | K9: 27 | L9: 41 | M9: 6 | N9: 29 | O9: 0
B10: Total transfer costs | C10: 16 | D10: 16 | E10: 4 | F10: 44 | G10: 20 | H10: 8 | I10: 24 | J10: 0 | K10: 0 | L10: 36 | M10: 4 | N10: 0 | O10: 0
B11: Total points on bench | C11: 235 | D11: 238 | E11: 291 | F11: 333 | G11: 264 | H11: 323 | I11: 252 | J11: 215 | K11: 199 | L11: 252 | M11: 142 | N11: 217 | O11: 70
B12: Unique players | C12: 63 | D12: 64 | E12: 61 | F12: 65 | G12: 61 | H12: 70 | I12: 56 | J12: 46 | K12: 48 | L12: 59 | M12: 21 | N12: 43 | O12: 23
B13: Unique captains | C13: 8 | D13: 9 | E13: 7 | F13: 8 | G13: 18 | H13: 12 | I13: 9 | J13: 6 | K13: 13 | L13: 7 | M13: 1 | N13: 3 | O13: 1
B15: Captain points | C15: 564 | D15: 546 | E15: 525 | F15: 526 | G15: 507 | H15: 478 | I15: 499 | J15: 553 | K15: 455 | L15: 508 | M15: 536 | N15: 517 | O15: 458
B16: Minutes | C16: 37322 | D16: 36530 | E16: 36404 | F16: 37700 | G16: 35927 | H16: 38133 | I16: 36230 | J16: 34190 | K16: 35124 | L16: 35981 | M16: 32116 | N16: 33897 | O16: 29416
... B28: BPS | C28: 8460 | D28: 8076 | E28: 8291 | F28: 8251 | G28: 7930 | H28: 8578 | I28: 8222 | J28: 7854 | K28: 7923 | L28: 7325 | M28: 7384 | N28: 7313 | O28: 6483

Sheet Pomocný
Q1: 13 | R1: 14 | S1: 15 | T1: 16 | U1: 17 | V1: 18 | W1: 19 | X1: 20 | Y1: 21 | Z1: 22 | AA1: 23 | AB1: 24 | AC1: 25 | AD1: 26 | AE1: 27 | AF1: 28 | AG1: 29 | AH1: 30 | AI1: 31 | AJ1: 32 | AK1: 33 | AL1: 34 | AM1: 35 | AN1: 36 | AO1: 37 | AP1: 38 | AQ1: 39 | AR1: 40 | AS1: 41 | AT1: 42 | AU1: 43 | AV1: 44 | AW1: 45 | AX1: 46 | AY1: 47 | AZ1: 48 | BA1: 49 | BB1: 50
C2: August | D2: September | E2: October | F2: November | G2: December | H2: January | I2: February | J2: March | K2: April | L2: May | Q2: GW 01 | R2: GW 02 | S2: GW 03 | T2: GW 04 | U2: GW 05 | V2: GW 06 | W2: GW 07 | X2: GW 08 | Y2: GW 09 | Z2: GW 10 | AA2: GW 11 | AB2: GW 12 | AC2: GW 13 | AD2: GW 14 | AE2: GW 15 | AF2: GW 16 | AG2: GW 17 | AH2: GW 18 | AI2: GW 19 | AJ2: GW 20 | AK2: GW 21 | AL2: GW 22 | AM2: GW 23 | AN2: GW 24 | AO2: GW 25 | AP2: GW 26 | AQ2: GW 27 | AR2: GW 28 | AS2: GW 29 | AT2: GW 30 | AU2: GW 31 | AV2: GW 32 | AW2: GW 33 | AX2: GW 34 | AY2: GW 35 | AZ2: GW 36 | BA2: GW 37 | BB2: GW 38
B3: Miroslav Pádivý | C3: =SUMPRODUCT(GW!$O$4:$AZ$14*(GW!$O$2:$AZ$2=C$2)*(GW!$C$4:$C$14=$B3)) -> 222 | D3: =SUMPRODUCT(GW!$O$4:$AZ$14*(GW!$O$2:$AZ$2=D$2)*(GW!$C$4:$C$14=$B3)) -> 156 | E3: =SUMPRODUCT(GW!$O$4:$AZ$14*(GW!$O$2:$AZ$2=E$2)*(GW!$C$4:$C$14=$B3)) -> 121 | F3: =SUMPRODUCT(GW!$O$4:$AZ$14*(GW!$O$2:$AZ$2=F$2)*(GW!$C$4:$C$14=$B3)) -> 205 | G3: =SUMPRODUCT(GW!$O$4:$AZ$14*(GW!$O$2:$AZ$2=G$2)*(GW!$C$4:$C$14=$B3)) -> 358 | H3: =SUMPRODUCT(GW!$O$4:$AZ$14*(GW!$O$2:$AZ$2=H$2)*(GW!$C$4:$C$14=$B3)) -> 210 | I3: =SUMPRODUCT(GW!$O$4:$AZ$14*(GW!$O$2:$AZ$2=I$2)*(GW!$C$4:$C$14=$B3)) -> 308 | J3: =SUMPRODUCT(GW!$O$4:$AZ$14*(GW!$O$2:$AZ$2=J$2)*(GW!$C$4:$C$14=$B3)) -> 141 | ... L3: =SUMPRODUCT(GW!$O$4:$AZ$14*(GW!$O$2:$AZ$2=L$2)*(GW!$C$4:$C$14=$B3)) -> 194 | M3: Miroslav Pádivý | O3: Miroslav Pádivý | P3: =SUM(Q3:BB3) -> 2 | Q3: =IF(VLOOKUP($O3,GW!$C:$AZ,'Pomocný'!Q$1,FALSE)=Q$14,1,0) -> 0 | R3: =IF(VLOOKUP($O3,GW!$C:$AZ,'Pomocný'!R$1,FALSE)=R$14,1,0) -> 0 | S3: =IF(VLOOKUP($O3,GW!$C:$AZ,'Pomocný'!S$1,FALSE)=S$14,1,0) -> 1 | T3: =IF(VLOOKUP($O3,GW!$C:$AZ,'Pomocný'!T$1,FALSE)=T$14,1,0) -> 0 | U3: =IF(VLOOKUP($O3,GW!$C:$AZ,'Pomocný'!U$1,FALSE)=U$14,1,0) -> 0 | V3: =IF(VLOOKUP($O3,GW!$C:$AZ,'Pomocný'!V$1,FALSE)=V$14,1,0) -> 0 | W3: =IF(VLOOKUP($O3,GW!$C:$AZ,'Pomocný'!W$1,FALSE)=W$14,1,0) -> 0 | X3: =IF(VLOOKUP($O3,GW!$C:$AZ,'Pomocný'!X$1,FALSE)=X$14,1,0) -> 0 | ... BB3: =IF(VLOOKUP($O3,GW!$C:$AZ,'Pomocný'!BB$1,FALSE)=BB$14,1,0) -> 0
B4: Martin Vácha | C4: =SUMPRODUCT(GW!$O$4:$AZ$14*(GW!$O$2:$AZ$2=C$2)*(GW!$C$4:$C$14=$B4)) -> 207 | D4: =SUMPRODUCT(GW!$O$4:$AZ$14*(GW!$O$2:$AZ$2=D$2)*(GW!$C$4:$C$14=$B4)) -> 191 | E4: =SUMPRODUCT(GW!$O$4:$AZ$14*(GW!$O$2:$AZ$2=E$2)*(GW!$C$4:$C$14=$B4)) -> 147 | F4: =SUMPRODUCT(GW!$O$4:$AZ$14*(GW!$O$2:$AZ$2=F$2)*(GW!$C$4:$C$14=$B4)) -> 199 | G4: =SUMPRODUCT(GW!$O$4:$AZ$14*(GW!$O$2:$AZ$2=G$2)*(GW!$C$4:$C$14=$B4)) -> 345 | H4: =SUMPRODUCT(GW!$O$4:$AZ$14*(GW!$O$2:$AZ$2=H$2)*(GW!$C$4:$C$14=$B4)) -> 251 | I4: =SUMPRODUCT(GW!$O$4:$AZ$14*(GW!$O$2:$AZ$2=I$2)*(GW!$C$4:$C$14=$B4)) -> 310 | J4: =SUMPRODUCT(GW!$O$4:$AZ$14*(GW!$O$2:$AZ$2=J$2)*(GW!$C$4:$C$14=$B4)) -> 99 | ... L4: =SUMPRODUCT(GW!$O$4:$AZ$14*(GW!$O$2:$AZ$2=L$2)*(GW!$C$4:$C$14=$B4)) -> 200 | M4: Martin Vácha | O4: Martin Vácha | P4: =SUM(Q4:BB4) -> 3 | Q4: =IF(VLOOKUP($O4,GW!$C:$AZ,'Pomocný'!Q$1,FALSE)=Q$14,1,0) -> 0 | R4: =IF(VLOOKUP($O4,GW!$C:$AZ,'Pomocný'!R$1,FALSE)=R$14,1,0) -> 0 | S4: =IF(VLOOKUP($O4,GW!$C:$AZ,'Pomocný'!S$1,FALSE)=S$14,1,0) -> 0 | T4: =IF(VLOOKUP($O4,GW!$C:$AZ,'Pomocný'!T$1,FALSE)=T$14,1,0) -> 0 | U4: =IF(VLOOKUP($O4,GW!$C:$AZ,'Pomocný'!U$1,FALSE)=U$14,1,0) -> 0 | V4: =IF(VLOOKUP($O4,GW!$C:$AZ,'Pomocný'!V$1,FALSE)=V$14,1,0) -> 0 | W4: =IF(VLOOKUP($O4,GW!$C:$AZ,'Pomocný'!W$1,FALSE)=W$14,1,0) -> 0 | X4: =IF(VLOOKUP($O4,GW!$C:$AZ,'Pomocný'!X$1,FALSE)=X$14,1,0) -> 0 | ... BB4: =IF(VLOOKUP($O4,GW!$C:$AZ,'Pomocný'!BB$1,FALSE)=BB$14,1,0) -> 0
B5: Milan Pádivý | C5: =SUMPRODUCT(GW!$O$4:$AZ$14*(GW!$O$2:$AZ$2=C$2)*(GW!$C$4:$C$14=$B5)) -> 222 | D5: =SUMPRODUCT(GW!$O$4:$AZ$14*(GW!$O$2:$AZ$2=D$2)*(GW!$C$4:$C$14=$B5)) -> 181 | E5: =SUMPRODUCT(GW!$O$4:$AZ$14*(GW!$O$2:$AZ$2=E$2)*(GW!$C$4:$C$14=$B5)) -> 178 | F5: =SUMPRODUCT(GW!$O$4:$AZ$14*(GW!$O$2:$AZ$2=F$2)*(GW!$C$4:$C$14=$B5)) -> 256 | G5: =SUMPRODUCT(GW!$O$4:$AZ$14*(GW!$O$2:$AZ$2=G$2)*(GW!$C$4:$C$14=$B5)) -> 326 | H5: =SUMPRODUCT(GW!$O$4:$AZ$14*(GW!$O$2:$AZ$2=H$2)*(GW!$C$4:$C$14=$B5)) -> 266 | I5: =SUMPRODUCT(GW!$O$4:$AZ$14*(GW!$O$2:$AZ$2=I$2)*(GW!$C$4:$C$14=$B5)) -> 304 | J5: =SUMPRODUCT(GW!$O$4:$AZ$14*(GW!$O$2:$AZ$2=J$2)*(GW!$C$4:$C$14=$B5)) -> 121 | ... L5: =SUMPRODUCT(GW!$O$4:$AZ$14*(GW!$O$2:$AZ$2=L$2)*(GW!$C$4:$C$14=$B5)) -> 208 | M5: Milan Pádivý | O5: Milan Pádivý | P5: =SUM(Q5:BB5) -> 8 | Q5: =IF(VLOOKUP($O5,GW!$C:$AZ,'Pomocný'!Q$1,FALSE)=Q$14,1,0) -> 1 | R5: =IF(VLOOKUP($O5,GW!$C:$AZ,'Pomocný'!R$1,FALSE)=R$14,1,0) -> 0 | S5: =IF(VLOOKUP($O5,GW!$C:$AZ,'Pomocný'!S$1,FALSE)=S$14,1,0) -> 0 | T5: =IF(VLOOKUP($O5,GW!$C:$AZ,'Pomocný'!T$1,FALSE)=T$14,1,0) -> 0 | U5: =IF(VLOOKUP($O5,GW!$C:$AZ,'Pomocný'!U$1,FALSE)=U$14,1,0) -> 0 | V5: =IF(VLOOKUP($O5,GW!$C:$AZ,'Pomocný'!V$1,FALSE)=V$14,1,0) -> 1 | W5: =IF(VLOOKUP($O5,GW!$C:$AZ,'Pomocný'!W$1,FALSE)=W$14,1,0) -> 0 | X5: =IF(VLOOKUP($O5,GW!$C:$AZ,'Pomocný'!X$1,FALSE)=X$14,1,0) -> 1 | ... BB5: =IF(VLOOKUP($O5,GW!$C:$AZ,'Pomocný'!BB$1,FALSE)=BB$14,1,0) -> 0
B6: Martin Šípek | C6: =SUMPRODUCT(GW!$O$4:$AZ$14*(GW!$O$2:$AZ$2=C$2)*(GW!$C$4:$C$14=$B6)) -> 250 | D6: =SUMPRODUCT(GW!$O$4:$AZ$14*(GW!$O$2:$AZ$2=D$2)*(GW!$C$4:$C$14=$B6)) -> 155 | E6: =SUMPRODUCT(GW!$O$4:$AZ$14*(GW!$O$2:$AZ$2=E$2)*(GW!$C$4:$C$14=$B6)) -> 123 | F6: =SUMPRODUCT(GW!$O$4:$AZ$14*(GW!$O$2:$AZ$2=F$2)*(GW!$C$4:$C$14=$B6)) -> 190 | G6: =SUMPRODUCT(GW!$O$4:$AZ$14*(GW!$O$2:$AZ$2=G$2)*(GW!$C$4:$C$14=$B6)) -> 279 | H6: =SUMPRODUCT(GW!$O$4:$AZ$14*(GW!$O$2:$AZ$2=H$2)*(GW!$C$4:$C$14=$B6)) -> 206 | I6: =SUMPRODUCT(GW!$O$4:$AZ$14*(GW!$O$2:$AZ$2=I$2)*(GW!$C$4:$C$14=$B6)) -> 371 | J6: =SUMPRODUCT(GW!$O$4:$AZ$14*(GW!$O$2:$AZ$2=J$2)*(GW!$C$4:$C$14=$B6)) -> 150 | ... L6: =SUMPRODUCT(GW!$O$4:$AZ$14*(GW!$O$2:$AZ$2=L$2)*(GW!$C$4:$C$14=$B6)) -> 218 | M6: Martin Šípek | O6: Martin Šípek | P6: =SUM(Q6:BB6) -> 4 | Q6: =IF(VLOOKUP($O6,GW!$C:$AZ,'Pomocný'!Q$1,FALSE)=Q$14,1,0) -> 0 | R6: =IF(VLOOKUP($O6,GW!$C:$AZ,'Pomocný'!R$1,FALSE)=R$14,1,0) -> 0 | S6: =IF(VLOOKUP($O6,GW!$C:$AZ,'Pomocný'!S$1,FALSE)=S$14,1,0) -> 0 | T6: =IF(VLOOKUP($O6,GW!$C:$AZ,'Pomocný'!T$1,FALSE)=T$14,1,0) -> 0 | U6: =IF(VLOOKUP($O6,GW!$C:$AZ,'Pomocný'!U$1,FALSE)=U$14,1,0) -> 0 | V6: =IF(VLOOKUP($O6,GW!$C:$AZ,'Pomocný'!V$1,FALSE)=V$14,1,0) -> 0 | W6: =IF(VLOOKUP($O6,GW!$C:$AZ,'Pomocný'!W$1,FALSE)=W$14,1,0) -> 0 | X6: =IF(VLOOKUP($O6,GW!$C:$AZ,'Pomocný'!X$1,FALSE)=X$14,1,0) -> 0 | ... BB6: =IF(VLOOKUP($O6,GW!$C:$AZ,'Pomocný'!BB$1,FALSE)=BB$14,1,0) -> 0
B7: Tomáš Kreps | C7: =SUMPRODUCT(GW!$O$4:$AZ$14*(GW!$O$2:$AZ$2=C$2)*(GW!$C$4:$C$14=$B7)) -> 218 | D7: =SUMPRODUCT(GW!$O$4:$AZ$14*(GW!$O$2:$AZ$2=D$2)*(GW!$C$4:$C$14=$B7)) -> 180 | E7: =SUMPRODUCT(GW!$O$4:$AZ$14*(GW!$O$2:$AZ$2=E$2)*(GW!$C$4:$C$14=$B7)) -> 165 | F7: =SUMPRODUCT(GW!$O$4:$AZ$14*(GW!$O$2:$AZ$2=F$2)*(GW!$C$4:$C$14=$B7)) -> 246 | G7: =SUMPRODUCT(GW!$O$4:$AZ$14*(GW!$O$2:$AZ$2=G$2)*(GW!$C$4:$C$14=$B7)) -> 391 | H7: =SUMPRODUCT(GW!$O$4:$AZ$14*(GW!$O$2:$AZ$2=H$2)*(GW!$C$4:$C$14=$B7)) -> 240 | I7: =SUMPRODUCT(GW!$O$4:$AZ$14*(GW!$O$2:$AZ$2=I$2)*(GW!$C$4:$C$14=$B7)) -> 354 | J7: =SUMPRODUCT(GW!$O$4:$AZ$14*(GW!$O$2:$AZ$2=J$2)*(GW!$C$4:$C$14=$B7)) -> 94 | ... L7: =SUMPRODUCT(GW!$O$4:$AZ$14*(GW!$O$2:$AZ$2=L$2)*(GW!$C$4:$C$14=$B7)) -> 236 | M7: Tomáš Kreps | O7: Tomáš Kreps | P7: =SUM(Q7:BB7) -> 4 | Q7: =IF(VLOOKUP($O7,GW!$C:$AZ,'Pomocný'!Q$1,FALSE)=Q$14,1,0) -> 0 | R7: =IF(VLOOKUP($O7,GW!$C:$AZ,'Pomocný'!R$1,FALSE)=R$14,1,0) -> 0 | S7: =IF(VLOOKUP($O7,GW!$C:$AZ,'Pomocný'!S$1,FALSE)=S$14,1,0) -> 0 | T7: =IF(VLOOKUP($O7,GW!$C:$AZ,'Pomocný'!T$1,FALSE)=T$14,1,0) -> 0 | U7: =IF(VLOOKUP($O7,GW!$C:$AZ,'Pomocný'!U$1,FALSE)=U$14,1,0) -> 0 | V7: =IF(VLOOKUP($O7,GW!$C:$AZ,'Pomocný'!V$1,FALSE)=V$14,1,0) -> 0 | W7: =IF(VLOOKUP($O7,GW!$C:$AZ,'Pomocný'!W$1,FALSE)=W$14,1,0) -> 0 | X7: =IF(VLOOKUP($O7,GW!$C:$AZ,'Pomocný'!X$1,FALSE)=X$14,1,0) -> 0 | ... BB7: =IF(VLOOKUP($O7,GW!$C:$AZ,'Pomocný'!BB$1,FALSE)=BB$14,1,0) -> 1
B8: Josef Mokráň | C8: =SUMPRODUCT(GW!$O$4:$AZ$14*(GW!$O$2:$AZ$2=C$2)*(GW!$C$4:$C$14=$B8)) -> 215 | D8: =SUMPRODUCT(GW!$O$4:$AZ$14*(GW!$O$2:$AZ$2=D$2)*(GW!$C$4:$C$14=$B8)) -> 166 | E8: =SUMPRODUCT(GW!$O$4:$AZ$14*(GW!$O$2:$AZ$2=E$2)*(GW!$C$4:$C$14=$B8)) -> 134 | F8: =SUMPRODUCT(GW!$O$4:$AZ$14*(GW!$O$2:$AZ$2=F$2)*(GW!$C$4:$C$14=$B8)) -> 179 | G8: =SUMPRODUCT(GW!$O$4:$AZ$14*(GW!$O$2:$AZ$2=G$2)*(GW!$C$4:$C$14=$B8)) -> 385 | H8: =SUMPRODUCT(GW!$O$4:$AZ$14*(GW!$O$2:$AZ$2=H$2)*(GW!$C$4:$C$14=$B8)) -> 236 | I8: =SUMPRODUCT(GW!$O$4:$AZ$14*(GW!$O$2:$AZ$2=I$2)*(GW!$C$4:$C$14=$B8)) -> 333 | J8: =SUMPRODUCT(GW!$O$4:$AZ$14*(GW!$O$2:$AZ$2=J$2)*(GW!$C$4:$C$14=$B8)) -> 127 | ... L8: =SUMPRODUCT(GW!$O$4:$AZ$14*(GW!$O$2:$AZ$2=L$2)*(GW!$C$4:$C$14=$B8)) -> 210 | M8: Josef Mokráň | O8: Josef Mokráň | P8: =SUM(Q8:BB8) -> 4 | Q8: =IF(VLOOKUP($O8,GW!$C:$AZ,'Pomocný'!Q$1,FALSE)=Q$14,1,0) -> 0 | R8: =IF(VLOOKUP($O8,GW!$C:$AZ,'Pomocný'!R$1,FALSE)=R$14,1,0) -> 0 | S8: =IF(VLOOKUP($O8,GW!$C:$AZ,'Pomocný'!S$1,FALSE)=S$14,1,0) -> 0 | T8: =IF(VLOOKUP($O8,GW!$C:$AZ,'Pomocný'!T$1,FALSE)=T$14,1,0) -> 1 | U8: =IF(VLOOKUP($O8,GW!$C:$AZ,'Pomocný'!U$1,FALSE)=U$14,1,0) -> 0 | V8: =IF(VLOOKUP($O8,GW!$C:$AZ,'Pomocný'!V$1,FALSE)=V$14,1,0) -> 0 | W8: =IF(VLOOKUP($O8,GW!$C:$AZ,'Pomocný'!W$1,FALSE)=W$14,1,0) -> 0 | X8: =IF(VLOOKUP($O8,GW!$C:$AZ,'Pomocný'!X$1,FALSE)=X$14,1,0) -> 0 | ... BB8: =IF(VLOOKUP($O8,GW!$C:$AZ,'Pomocný'!BB$1,FALSE)=BB$14,1,0) -> 0
B9: Milan Procházka | C9: =SUMPRODUCT(GW!$O$4:$AZ$14*(GW!$O$2:$AZ$2=C$2)*(GW!$C$4:$C$14=$B9)) -> 175 | D9: =SUMPRODUCT(GW!$O$4:$AZ$14*(GW!$O$2:$AZ$2=D$2)*(GW!$C$4:$C$14=$B9)) -> 170 | E9: =SUMPRODUCT(GW!$O$4:$AZ$14*(GW!$O$2:$AZ$2=E$2)*(GW!$C$4:$C$14=$B9)) -> 151 | F9: =SUMPRODUCT(GW!$O$4:$AZ$14*(GW!$O$2:$AZ$2=F$2)*(GW!$C$4:$C$14=$B9)) -> 177 | G9: =SUMPRODUCT(GW!$O$4:$AZ$14*(GW!$O$2:$AZ$2=G$2)*(GW!$C$4:$C$14=$B9)) -> 384 | H9: =SUMPRODUCT(GW!$O$4:$AZ$14*(GW!$O$2:$AZ$2=H$2)*(GW!$C$4:$C$14=$B9)) -> 252 | I9: =SUMPRODUCT(GW!$O$4:$AZ$14*(GW!$O$2:$AZ$2=I$2)*(GW!$C$4:$C$14=$B9)) -> 331 | J9: =SUMPRODUCT(GW!$O$4:$AZ$14*(GW!$O$2:$AZ$2=J$2)*(GW!$C$4:$C$14=$B9)) -> 121 | ... L9: =SUMPRODUCT(GW!$O$4:$AZ$14*(GW!$O$2:$AZ$2=L$2)*(GW!$C$4:$C$14=$B9)) -> 205 | M9: Milan Procházka | O9: Milan Procházka | P9: =SUM(Q9:BB9) -> 4 | Q9: =IF(VLOOKUP($O9,GW!$C:$AZ,'Pomocný'!Q$1,FALSE)=Q$14,1,0) -> 0 | R9: =IF(VLOOKUP($O9,GW!$C:$AZ,'Pomocný'!R$1,FALSE)=R$14,1,0) -> 0 | S9: =IF(VLOOKUP($O9,GW!$C:$AZ,'Pomocný'!S$1,FALSE)=S$14,1,0) -> 0 | T9: =IF(VLOOKUP($O9,GW!$C:$AZ,'Pomocný'!T$1,FALSE)=T$14,1,0) -> 0 | U9: =IF(VLOOKUP($O9,GW!$C:$AZ,'Pomocný'!U$1,FALSE)=U$14,1,0) -> 0 | V9: =IF(VLOOKUP($O9,GW!$C:$AZ,'Pomocný'!V$1,FALSE)=V$14,1,0) -> 0 | W9: =IF(VLOOKUP($O9,GW!$C:$AZ,'Pomocný'!W$1,FALSE)=W$14,1,0) -> 0 | X9: =IF(VLOOKUP($O9,GW!$C:$AZ,'Pomocný'!X$1,FALSE)=X$14,1,0) -> 0 | ... BB9: =IF(VLOOKUP($O9,GW!$C:$AZ,'Pomocný'!BB$1,FALSE)=BB$14,1,0) -> 0
B10: Miroslav Paňák | C10: =SUMPRODUCT(GW!$O$4:$AZ$14*(GW!$O$2:$AZ$2=C$2)*(GW!$C$4:$C$14=$B10)) -> 190 | D10: =SUMPRODUCT(GW!$O$4:$AZ$14*(GW!$O$2:$AZ$2=D$2)*(GW!$C$4:$C$14=$B10)) -> 204 | E10: =SUMPRODUCT(GW!$O$4:$AZ$14*(GW!$O$2:$AZ$2=E$2)*(GW!$C$4:$C$14=$B10)) -> 163 | F10: =SUMPRODUCT(GW!$O$4:$AZ$14*(GW!$O$2:$AZ$2=F$2)*(GW!$C$4:$C$14=$B10)) -> 219 | G10: =SUMPRODUCT(GW!$O$4:$AZ$14*(GW!$O$2:$AZ$2=G$2)*(GW!$C$4:$C$14=$B10)) -> 288 | H10: =SUMPRODUCT(GW!$O$4:$AZ$14*(GW!$O$2:$AZ$2=H$2)*(GW!$C$4:$C$14=$B10)) -> 223 | I10: =SUMPRODUCT(GW!$O$4:$AZ$14*(GW!$O$2:$AZ$2=I$2)*(GW!$C$4:$C$14=$B10)) -> 206 | J10: =SUMPRODUCT(GW!$O$4:$AZ$14*(GW!$O$2:$AZ$2=J$2)*(GW!$C$4:$C$14=$B10)) -> 77 | ... L10: =SUMPRODUCT(GW!$O$4:$AZ$14*(GW!$O$2:$AZ$2=L$2)*(GW!$C$4:$C$14=$B10)) -> 179 | M10: Miroslav Paňák | O10: Miroslav Paňák | P10: =SUM(Q10:BB10) -> 1 | Q10: =IF(VLOOKUP($O10,GW!$C:$AZ,'Pomocný'!Q$1,FALSE)=Q$14,1,0) -> 0 | R10: =IF(VLOOKUP($O10,GW!$C:$AZ,'Pomocný'!R$1,FALSE)=R$14,1,0) -> 0 | S10: =IF(VLOOKUP($O10,GW!$C:$AZ,'Pomocný'!S$1,FALSE)=S$14,1,0) -> 0 | T10: =IF(VLOOKUP($O10,GW!$C:$AZ,'Pomocný'!T$1,FALSE)=T$14,1,0) -> 0 | U10: =IF(VLOOKUP($O10,GW!$C:$AZ,'Pomocný'!U$1,FALSE)=U$14,1,0) -> 0 | V10: =IF(VLOOKUP($O10,GW!$C:$AZ,'Pomocný'!V$1,FALSE)=V$14,1,0) -> 0 | W10: =IF(VLOOKUP($O10,GW!$C:$AZ,'Pomocný'!W$1,FALSE)=W$14,1,0) -> 0 | X10: =IF(VLOOKUP($O10,GW!$C:$AZ,'Pomocný'!X$1,FALSE)=X$14,1,0) -> 0 | ... BB10: =IF(VLOOKUP($O10,GW!$C:$AZ,'Pomocný'!BB$1,FALSE)=BB$14,1,0) -> 0
B11: Denis Dvořák | C11: =SUMPRODUCT(GW!$O$4:$AZ$14*(GW!$O$2:$AZ$2=C$2)*(GW!$C$4:$C$14=$B11)) -> 211 | D11: =SUMPRODUCT(GW!$O$4:$AZ$14*(GW!$O$2:$AZ$2=D$2)*(GW!$C$4:$C$14=$B11)) -> 178 | E11: =SUMPRODUCT(GW!$O$4:$AZ$14*(GW!$O$2:$AZ$2=E$2)*(GW!$C$4:$C$14=$B11)) -> 127 | F11: =SUMPRODUCT(GW!$O$4:$AZ$14*(GW!$O$2:$AZ$2=F$2)*(GW!$C$4:$C$14=$B11)) -> 212 | G11: =SUMPRODUCT(GW!$O$4:$AZ$14*(GW!$O$2:$AZ$2=G$2)*(GW!$C$4:$C$14=$B11)) -> 378 | H11: =SUMPRODUCT(GW!$O$4:$AZ$14*(GW!$O$2:$AZ$2=H$2)*(GW!$C$4:$C$14=$B11)) -> 236 | I11: =SUMPRODUCT(GW!$O$4:$AZ$14*(GW!$O$2:$AZ$2=I$2)*(GW!$C$4:$C$14=$B11)) -> 321 | J11: =SUMPRODUCT(GW!$O$4:$AZ$14*(GW!$O$2:$AZ$2=J$2)*(GW!$C$4:$C$14=$B11)) -> 115 | ... L11: =SUMPRODUCT(GW!$O$4:$AZ$14*(GW!$O$2:$AZ$2=L$2)*(GW!$C$4:$C$14=$B11)) -> 182 | M11: Denis Dvořák | O11: Denis Dvořák | P11: =SUM(Q11:BB11) -> 4 | Q11: =IF(VLOOKUP($O11,GW!$C:$AZ,'Pomocný'!Q$1,FALSE)=Q$14,1,0) -> 0 | R11: =IF(VLOOKUP($O11,GW!$C:$AZ,'Pomocný'!R$1,FALSE)=R$14,1,0) -> 1 | S11: =IF(VLOOKUP($O11,GW!$C:$AZ,'Pomocný'!S$1,FALSE)=S$14,1,0) -> 0 | T11: =IF(VLOOKUP($O11,GW!$C:$AZ,'Pomocný'!T$1,FALSE)=T$14,1,0) -> 0 | U11: =IF(VLOOKUP($O11,GW!$C:$AZ,'Pomocný'!U$1,FALSE)=U$14,1,0) -> 0 | V11: =IF(VLOOKUP($O11,GW!$C:$AZ,'Pomocný'!V$1,FALSE)=V$14,1,0) -> 0 | W11: =IF(VLOOKUP($O11,GW!$C:$AZ,'Pomocný'!W$1,FALSE)=W$14,1,0) -> 0 | X11: =IF(VLOOKUP($O11,GW!$C:$AZ,'Pomocný'!X$1,FALSE)=X$14,1,0) -> 0 | ... BB11: =IF(VLOOKUP($O11,GW!$C:$AZ,'Pomocný'!BB$1,FALSE)=BB$14,1,0) -> 0
B12: Tomáš Čedík | C12: =SUMPRODUCT(GW!$O$4:$AZ$14*(GW!$O$2:$AZ$2=C$2)*(GW!$C$4:$C$14=$B12)) -> 136 | D12: =SUMPRODUCT(GW!$O$4:$AZ$14*(GW!$O$2:$AZ$2=D$2)*(GW!$C$4:$C$14=$B12)) -> 202 | E12: =SUMPRODUCT(GW!$O$4:$AZ$14*(GW!$O$2:$AZ$2=E$2)*(GW!$C$4:$C$14=$B12)) -> 150 | F12: =SUMPRODUCT(GW!$O$4:$AZ$14*(GW!$O$2:$AZ$2=F$2)*(GW!$C$4:$C$14=$B12)) -> 192 | G12: =SUMPRODUCT(GW!$O$4:$AZ$14*(GW!$O$2:$AZ$2=G$2)*(GW!$C$4:$C$14=$B12)) -> 236 | H12: =SUMPRODUCT(GW!$O$4:$AZ$14*(GW!$O$2:$AZ$2=H$2)*(GW!$C$4:$C$14=$B12)) -> 218 | I12: =SUMPRODUCT(GW!$O$4:$AZ$14*(GW!$O$2:$AZ$2=I$2)*(GW!$C$4:$C$14=$B12)) -> 354 | J12: =SUMPRODUCT(GW!$O$4:$AZ$14*(GW!$O$2:$AZ$2=J$2)*(GW!$C$4:$C$14=$B12)) -> 145 | ... L12: =SUMPRODUCT(GW!$O$4:$AZ$14*(GW!$O$2:$AZ$2=L$2)*(GW!$C$4:$C$14=$B12)) -> 194 | M12: Tomáš Čedík | O12: Tomáš Čedík | P12: =SUM(Q12:BB12) -> 6 | Q12: =IF(VLOOKUP($O12,GW!$C:$AZ,'Pomocný'!Q$1,FALSE)=Q$14,1,0) -> 0 | R12: =IF(VLOOKUP($O12,GW!$C:$AZ,'Pomocný'!R$1,FALSE)=R$14,1,0) -> 0 | S12: =IF(VLOOKUP($O12,GW!$C:$AZ,'Pomocný'!S$1,FALSE)=S$14,1,0) -> 0 | T12: =IF(VLOOKUP($O12,GW!$C:$AZ,'Pomocný'!T$1,FALSE)=T$14,1,0) -> 1 | U12: =IF(VLOOKUP($O12,GW!$C:$AZ,'Pomocný'!U$1,FALSE)=U$14,1,0) -> 1 | V12: =IF(VLOOKUP($O12,GW!$C:$AZ,'Pomocný'!V$1,FALSE)=V$14,1,0) -> 0 | W12: =IF(VLOOKUP($O12,GW!$C:$AZ,'Pomocný'!W$1,FALSE)=W$14,1,0) -> 1 | X12: =IF(VLOOKUP($O12,GW!$C:$AZ,'Pomocný'!X$1,FALSE)=X$14,1,0) -> 0 | ... BB12: =IF(VLOOKUP($O12,GW!$C:$AZ,'Pomocný'!BB$1,FALSE)=BB$14,1,0) -> 0
B13: Michal Marek | L13: =SUMPRODUCT(GW!$O$5:$AZ$14*(GW!$O$2:$AZ$2=L$2)*(GW!$C$5:$C$14=$B13)) -> 0 | M13: Michal Marek | O13: Michal Marek | P13: =SUM(Q13:BB13) -> #N/A | Q13: =IF(VLOOKUP($O13,GW!$C:$AZ,'Pomocný'!Q$1,FALSE)=Q$14,1,0) -> #N/A | R13: =IF(VLOOKUP($O13,GW!$C:$AZ,'Pomocný'!R$1,FALSE)=R$14,1,0) -> #N/A | S13: =IF(VLOOKUP($O13,GW!$C:$AZ,'Pomocný'!S$1,FALSE)=S$14,1,0) -> #N/A | T13: =IF(VLOOKUP($O13,GW!$C:$AZ,'Pomocný'!T$1,FALSE)=T$14,1,0) -> #N/A | U13: =IF(VLOOKUP($O13,GW!$C:$AZ,'Pomocný'!U$1,FALSE)=U$14,1,0) -> #N/A | V13: =IF(VLOOKUP($O13,GW!$C:$AZ,'Pomocný'!V$1,FALSE)=V$14,1,0) -> #N/A | W13: =IF(VLOOKUP($O13,GW!$C:$AZ,'Pomocný'!W$1,FALSE)=W$14,1,0) -> #N/A | X13: =IF(VLOOKUP($O13,GW!$C:$AZ,'Pomocný'!X$1,FALSE)=X$14,1,0) -> #N/A | ... BB13: =IF(VLOOKUP($O13,GW!$C:$AZ,'Pomocný'!BB$1,FALSE)=BB$14,1,0) -> #N/A
Q14: =IF(HLOOKUP(Q2,GW!3:14,2,FALSE)=0,-1,MAX(GW!O$4:O$14)) -> 94 | R14: =IF(HLOOKUP(R2,GW!3:14,2,FALSE)=0,-1,MAX(GW!P$4:P$14)) -> 109 | S14: =IF(HLOOKUP(S2,GW!3:14,2,FALSE)=0,-1,MAX(GW!Q$4:Q$14)) -> 85 | T14: =IF(HLOOKUP(T2,GW!3:14,2,FALSE)=0,-1,MAX(GW!R$4:R$14)) -> 67 | U14: =IF(HLOOKUP(U2,GW!3:14,2,FALSE)=0,-1,MAX(GW!S$4:S$14)) -> 77 | V14: =IF(HLOOKUP(V2,GW!3:14,2,FALSE)=0,-1,MAX(GW!T$4:T$14)) -> 106 | W14: =IF(HLOOKUP(W2,GW!3:14,2,FALSE)=0,-1,MAX(GW!U$4:U$14)) -> 76 | X14: =IF(HLOOKUP(X2,GW!3:14,2,FALSE)=0,-1,MAX(GW!V$4:V$14)) -> 59 | ... BB14: =IF(HLOOKUP(BB2,GW!3:14,2,FALSE)=0,-1,MAX(GW!AZ$4:AZ$14)) -> 74
B16: Miroslav Pádivý | C16: =RANK(C3,C$3:C$13) -> 2 | D16: =RANK(D3,D$3:D$13) -> 9 | E16: =IF(E3=0,"",RANK(E3,E$3:E$13)) -> 10 | F16: =IF(F3=0,"",RANK(F3,F$3:F$13)) -> 5 | G16: =IF(G3=0,"",RANK(G3,G$3:G$13)) -> 5 | H16: =IF(H3=0,"",RANK(H3,H$3:H$13)) -> 9 | I16: =IF(I3=0,"",RANK(I3,I$3:I$13)) -> 8 | J16: =IF(J3=0,"",RANK(J3,J$3:J$13)) -> 3 | K16: =IF(K3=0,"",RANK(K3,K$3:K$13)) -> 4 | L16: =IF(L3=0,"",RANK(L3,L$3:L$13)) -> 7 | M16: Miroslav Pádivý | O16: Miroslav Pádivý | P16: =SUM(Q16:BB16) -> 2 | Q16: =IF(VLOOKUP($O16,GW!$C:$AZ,'Pomocný'!Q$1,FALSE)=Q$27,1,0) -> 0 | R16: =IF(VLOOKUP($O16,GW!$C:$AZ,'Pomocný'!R$1,FALSE)=R$27,1,0) -> 0 | S16: =IF(VLOOKUP($O16,GW!$C:$AZ,'Pomocný'!S$1,FALSE)=S$27,1,0) -> 0 | T16: =IF(VLOOKUP($O16,GW!$C:$AZ,'Pomocný'!T$1,FALSE)=T$27,1,0) -> 0 | U16: =IF(VLOOKUP($O16,GW!$C:$AZ,'Pomocný'!U$1,FALSE)=U$27,1,0) -> 0 | V16: =IF(VLOOKUP($O16,GW!$C:$AZ,'Pomocný'!V$1,FALSE)=V$27,1,0) -> 0 | W16: =IF(VLOOKUP($O16,GW!$C:$AZ,'Pomocný'!W$1,FALSE)=W$27,1,0) -> 0 | X16: =IF(VLOOKUP($O16,GW!$C:$AZ,'Pomocný'!X$1,FALSE)=X$27,1,0) -> 0 | ... BB16: =IF(VLOOKUP($O16,GW!$C:$AZ,'Pomocný'!BB$1,FALSE)=BB$27,1,0) -> 0
B17: Martin Vácha | C17: =RANK(C4,C$3:C$13) -> 7 | D17: =RANK(D4,D$3:D$13) -> 3 | E17: =IF(E4=0,"",RANK(E4,E$3:E$13)) -> 6 | F17: =IF(F4=0,"",RANK(F4,F$3:F$13)) -> 6 | G17: =IF(G4=0,"",RANK(G4,G$3:G$13)) -> 6 | H17: =IF(H4=0,"",RANK(H4,H$3:H$13)) -> 3 | I17: =IF(I4=0,"",RANK(I4,I$3:I$13)) -> 7 | J17: =IF(J4=0,"",RANK(J4,J$3:J$13)) -> 8 | K17: =IF(K4=0,"",RANK(K4,K$3:K$13)) -> 5 | L17: =IF(L4=0,"",RANK(L4,L$3:L$13)) -> 6 | M17: Martin Vácha | O17: Martin Vácha | P17: =SUM(Q17:BB17) -> 2 | Q17: =IF(VLOOKUP($O17,GW!$C:$AZ,'Pomocný'!Q$1,FALSE)=Q$27,1,0) -> 0 | R17: =IF(VLOOKUP($O17,GW!$C:$AZ,'Pomocný'!R$1,FALSE)=R$27,1,0) -> 0 | S17: =IF(VLOOKUP($O17,GW!$C:$AZ,'Pomocný'!S$1,FALSE)=S$27,1,0) -> 0 | T17: =IF(VLOOKUP($O17,GW!$C:$AZ,'Pomocný'!T$1,FALSE)=T$27,1,0) -> 0 | U17: =IF(VLOOKUP($O17,GW!$C:$AZ,'Pomocný'!U$1,FALSE)=U$27,1,0) -> 0 | V17: =IF(VLOOKUP($O17,GW!$C:$AZ,'Pomocný'!V$1,FALSE)=V$27,1,0) -> 0 | W17: =IF(VLOOKUP($O17,GW!$C:$AZ,'Pomocný'!W$1,FALSE)=W$27,1,0) -> 0 | X17: =IF(VLOOKUP($O17,GW!$C:$AZ,'Pomocný'!X$1,FALSE)=X$27,1,0) -> 0 | ... BB17: =IF(VLOOKUP($O17,GW!$C:$AZ,'Pomocný'!BB$1,FALSE)=BB$27,1,0) -> 1
B18: Milan Pádivý | C18: =RANK(C5,C$3:C$13) -> 2 | D18: =RANK(D5,D$3:D$13) -> 4 | E18: =IF(E5=0,"",RANK(E5,E$3:E$13)) -> 1 | F18: =IF(F5=0,"",RANK(F5,F$3:F$13)) -> 1 | G18: =IF(G5=0,"",RANK(G5,G$3:G$13)) -> 7 | H18: =IF(H5=0,"",RANK(H5,H$3:H$13)) -> 1 | I18: =IF(I5=0,"",RANK(I5,I$3:I$13)) -> 9 | J18: =IF(J5=0,"",RANK(J5,J$3:J$13)) -> 5 | K18: =IF(K5=0,"",RANK(K5,K$3:K$13)) -> 2 | L18: =IF(L5=0,"",RANK(L5,L$3:L$13)) -> 4 | M18: Milan Pádivý | O18: Milan Pádivý | P18: =SUM(Q18:BB18) -> 3 | Q18: =IF(VLOOKUP($O18,GW!$C:$AZ,'Pomocný'!Q$1,FALSE)=Q$27,1,0) -> 0 | R18: =IF(VLOOKUP($O18,GW!$C:$AZ,'Pomocný'!R$1,FALSE)=R$27,1,0) -> 0 | S18: =IF(VLOOKUP($O18,GW!$C:$AZ,'Pomocný'!S$1,FALSE)=S$27,1,0) -> 0 | T18: =IF(VLOOKUP($O18,GW!$C:$AZ,'Pomocný'!T$1,FALSE)=T$27,1,0) -> 1 | U18: =IF(VLOOKUP($O18,GW!$C:$AZ,'Pomocný'!U$1,FALSE)=U$27,1,0) -> 1 | V18: =IF(VLOOKUP($O18,GW!$C:$AZ,'Pomocný'!V$1,FALSE)=V$27,1,0) -> 0 | W18: =IF(VLOOKUP($O18,GW!$C:$AZ,'Pomocný'!W$1,FALSE)=W$27,1,0) -> 0 | X18: =IF(VLOOKUP($O18,GW!$C:$AZ,'Pomocný'!X$1,FALSE)=X$27,1,0) -> 0 | ... BB18: =IF(VLOOKUP($O18,GW!$C:$AZ,'Pomocný'!BB$1,FALSE)=BB$27,1,0) -> 0
B19: Martin Šípek | C19: =RANK(C6,C$3:C$13) -> 1 | D19: =RANK(D6,D$3:D$13) -> 10 | E19: =IF(E6=0,"",RANK(E6,E$3:E$13)) -> 9 | F19: =IF(F6=0,"",RANK(F6,F$3:F$13)) -> 8 | G19: =IF(G6=0,"",RANK(G6,G$3:G$13)) -> 9 | H19: =IF(H6=0,"",RANK(H6,H$3:H$13)) -> 10 | I19: =IF(I6=0,"",RANK(I6,I$3:I$13)) -> 1 | J19: =IF(J6=0,"",RANK(J6,J$3:J$13)) -> 1 | K19: =IF(K6=0,"",RANK(K6,K$3:K$13)) -> 9 | L19: =IF(L6=0,"",RANK(L6,L$3:L$13)) -> 2 | M19: Martin Šípek | O19: Martin Šípek | P19: =SUM(Q19:BB19) -> 8 | Q19: =IF(VLOOKUP($O19,GW!$C:$AZ,'Pomocný'!Q$1,FALSE)=Q$27,1,0) -> 0 | R19: =IF(VLOOKUP($O19,GW!$C:$AZ,'Pomocný'!R$1,FALSE)=R$27,1,0) -> 0 | S19: =IF(VLOOKUP($O19,GW!$C:$AZ,'Pomocný'!S$1,FALSE)=S$27,1,0) -> 0 | T19: =IF(VLOOKUP($O19,GW!$C:$AZ,'Pomocný'!T$1,FALSE)=T$27,1,0) -> 0 | U19: =IF(VLOOKUP($O19,GW!$C:$AZ,'Pomocný'!U$1,FALSE)=U$27,1,0) -> 1 | V19: =IF(VLOOKUP($O19,GW!$C:$AZ,'Pomocný'!V$1,FALSE)=V$27,1,0) -> 0 | W19: =IF(VLOOKUP($O19,GW!$C:$AZ,'Pomocný'!W$1,FALSE)=W$27,1,0) -> 0 | X19: =IF(VLOOKUP($O19,GW!$C:$AZ,'Pomocný'!X$1,FALSE)=X$27,1,0) -> 1 | ... BB19: =IF(VLOOKUP($O19,GW!$C:$AZ,'Pomocný'!BB$1,FALSE)=BB$27,1,0) -> 0
B20: Tomáš Kreps | C20: =RANK(C7,C$3:C$13) -> 4 | D20: =RANK(D7,D$3:D$13) -> 5 | E20: =IF(E7=0,"",RANK(E7,E$3:E$13)) -> 2 | F20: =IF(F7=0,"",RANK(F7,F$3:F$13)) -> 2 | G20: =IF(G7=0,"",RANK(G7,G$3:G$13)) -> 1 | H20: =IF(H7=0,"",RANK(H7,H$3:H$13)) -> 4 | I20: =IF(I7=0,"",RANK(I7,I$3:I$13)) -> 2 | J20: =IF(J7=0,"",RANK(J7,J$3:J$13)) -> 9 | K20: =IF(K7=0,"",RANK(K7,K$3:K$13)) -> 3 | L20: =IF(L7=0,"",RANK(L7,L$3:L$13)) -> 1 | M20: Tomáš Kreps | O20: Tomáš Kreps | P20: =SUM(Q20:BB20) -> 1 | Q20: =IF(VLOOKUP($O20,GW!$C:$AZ,'Pomocný'!Q$1,FALSE)=Q$27,1,0) -> 0 | R20: =IF(VLOOKUP($O20,GW!$C:$AZ,'Pomocný'!R$1,FALSE)=R$27,1,0) -> 0 | S20: =IF(VLOOKUP($O20,GW!$C:$AZ,'Pomocný'!S$1,FALSE)=S$27,1,0) -> 0 | T20: =IF(VLOOKUP($O20,GW!$C:$AZ,'Pomocný'!T$1,FALSE)=T$27,1,0) -> 0 | U20: =IF(VLOOKUP($O20,GW!$C:$AZ,'Pomocný'!U$1,FALSE)=U$27,1,0) -> 0 | V20: =IF(VLOOKUP($O20,GW!$C:$AZ,'Pomocný'!V$1,FALSE)=V$27,1,0) -> 0 | W20: =IF(VLOOKUP($O20,GW!$C:$AZ,'Pomocný'!W$1,FALSE)=W$27,1,0) -> 0 | X20: =IF(VLOOKUP($O20,GW!$C:$AZ,'Pomocný'!X$1,FALSE)=X$27,1,0) -> 0 | ... BB20: =IF(VLOOKUP($O20,GW!$C:$AZ,'Pomocný'!BB$1,FALSE)=BB$27,1,0) -> 0
B21: Josef Mokráň | C21: =RANK(C8,C$3:C$13) -> 5 | D21: =RANK(D8,D$3:D$13) -> 8 | E21: =IF(E8=0,"",RANK(E8,E$3:E$13)) -> 7 | F21: =IF(F8=0,"",RANK(F8,F$3:F$13)) -> 9 | G21: =IF(G8=0,"",RANK(G8,G$3:G$13)) -> 2 | H21: =IF(H8=0,"",RANK(H8,H$3:H$13)) -> 5 | I21: =IF(I8=0,"",RANK(I8,I$3:I$13)) -> 4 | J21: =IF(J8=0,"",RANK(J8,J$3:J$13)) -> 4 | K21: =IF(K8=0,"",RANK(K8,K$3:K$13)) -> 1 | L21: =IF(L8=0,"",RANK(L8,L$3:L$13)) -> 3 | M21: Josef Mokráň | O21: Josef Mokráň | P21: =SUM(Q21:BB21) -> 3 | Q21: =IF(VLOOKUP($O21,GW!$C:$AZ,'Pomocný'!Q$1,FALSE)=Q$27,1,0) -> 0 | R21: =IF(VLOOKUP($O21,GW!$C:$AZ,'Pomocný'!R$1,FALSE)=R$27,1,0) -> 0 | S21: =IF(VLOOKUP($O21,GW!$C:$AZ,'Pomocný'!S$1,FALSE)=S$27,1,0) -> 0 | T21: =IF(VLOOKUP($O21,GW!$C:$AZ,'Pomocný'!T$1,FALSE)=T$27,1,0) -> 0 | U21: =IF(VLOOKUP($O21,GW!$C:$AZ,'Pomocný'!U$1,FALSE)=U$27,1,0) -> 0 | V21: =IF(VLOOKUP($O21,GW!$C:$AZ,'Pomocný'!V$1,FALSE)=V$27,1,0) -> 1 | W21: =IF(VLOOKUP($O21,GW!$C:$AZ,'Pomocný'!W$1,FALSE)=W$27,1,0) -> 0 | X21: =IF(VLOOKUP($O21,GW!$C:$AZ,'Pomocný'!X$1,FALSE)=X$27,1,0) -> 0 | ... BB21: =IF(VLOOKUP($O21,GW!$C:$AZ,'Pomocný'!BB$1,FALSE)=BB$27,1,0) -> 0
